Workbook

Sheet 1.건전성
A1: 회사명 | B1: 사업보고서 바로가기 | C1: 종목코드 | D1: 경실련 업종 | E1: 업종 | F1: 주요제품 | G1: 상장일 | H1: 결산월 | I1: 대표자명 | J1: 홈페이지 | K1: 지역 | L1: 자산총계 (천원) | M1: 부채총계 (천원) | N1: 자본총계 (천원) | O1: 매출액 (천원) | P1: 영업이익 (천원) | Q1: 법인세차감전 계속사업이익 (천원) | R1: 당기순이익 (천원) | S1: 발행주식 총수 (보통주) | T1: 자기주식수 (보통주) | U1: 동일인지분 (주식수) | V1: 친족지분 (주식수) | W1: 임원지분 (주식수) | X1: 비영리법인지분 (주식수) | Y1: 비영리법인 법인명 (입력) | Z1: 계열회사지분 (주식수) | AA1: 상호주 (주식수) | AB1: 내부지분수 (합계) | AC1: 내부지분율 | AD1: 내부지분율 (100점) | AE1: 1. 내부지분율 (제조·비제조3점/금융4점) | AF1: 소유지분율 | AG1: 의결지분율 | AH1: 소유지배 괴리도 (%) | AI1: 소유지배 괴리도 (100) | AJ1: 2.소유지배괴리도 (제조·비제조4점/금융5점) | AK1: 등기 임원수 (명) | AL1: 미등기 임원수 (명) | AM1: 1%이상 주식보유 임원수 (명) | AN1: 총임원수(명) | AO1: 전문경영인정도(%) | AP1: 전문경영인정도 평점화 (100) | AQ1: 3.전문경영인정도 (제조·비제조2점/금융3점) | AR1: 사외이사수 (명) | AS1: 법정사외이사수 (%) (총자산 2조원 기준) | AT1: 법정사외이사수 | AU1: (소수점 절상) | AV1: 사외이사비율(%) | AW1: 사외이사비율 평점화 (100) | AX1: 4. 사외이사비율 (제조·비제조1점/금융2점) | AY1: 이사회 개최건수 (건) | AZ1: 실제 누적 참석수 (명) | BA1: 총 누적 참석 수 | BB1: 사외이사 참여도(%) | BC1: 이사회 참여도 (100) | BD1: 5. 이사회 참여 (제조·비제조1점/금융2점) | BE1: 급여 (천원) | BF1: 퇴직급여 (천원) | BG1: 접대비/교재비 (천원) | BH1: 인건비 (천원) | BI1: 소비성지출(%) (접대비/인건비) | BJ1: 업종 | BK1: 업종별 평균 | BL1: 소비성지출 편차 (소비성지출-평균) | BM1: 소비성지출(100) | BN1: 6. 소비성지출 (모두 2점) | BO1: 연구개발비 (천원) | BP1: 연구개발지출(%) | BQ1: 연구개발지출 (100) | BR1: 7.연구개발 (제조·비제조2점/금융1점) | BS1: 유형자산 취득 (천원) | BT1: 유형자산 처분 (천원) | BU1: 설비투자액 (천원) | BV1: 설비투자율(%) | BW1: 업종별 설비투자율 평균 (%) | BX1: 설비투자율 분산값 | BY1: 매출대비 업종별 설비투자율 표준편차 | BZ1: 매출대비 업종별 설비투자액 상위(%) | CA1: 업종별 설비투자액 (100점) | CB1: 8. 설비투자 (모두 2점) | CC1: 위험성 (%) | CD1: 위험성 (100점) | CE1: 9. 부채비율 (제조·비제조1.5점/금융업 제외) | CF1: 고정이하 여신비율 (은행, 종금) (%) | CG1: 고정이하 자산비율 (증권) (%) | CH1: 위험가중 자산비율 (보험) (%) | CI1: 위험성(100) | CJ1: 10. 고정이하 여신/ 자산/위험가중자산비율 (금융업 4점/제조·비제조 제외) | CK1: 회사채신용등급 (입력) | CL1: 6등급 분류 (A ~ F) | CM1: 회사채 신용등급 (100) | CN1: 11. 회사채 신용등급 (제조·비제조1.5점/금융3점) | CO1: 관계사 출자금액 (천원) | CP1: 관계사출자(%) | CQ1: 관계사 출자금액 (100) | CR1: 12. 관계사 출자금액 (제조·비제조 3점/금융4점) | CS1: 관계사 채무보증액 (천원) | CT1: 관계사채무보증액(%) | CU1: 관계사채무보증액(100) | CV1: 13. 관계사채무보증 (제조·비제조2점/금융3점) | CW1: 건전성 (제조·비제조 25점/금융업 35점)
A2: BGF리테일 | B2: https://dart.fss.or.kr/dsaf001/main.do?rcpNo=20230320000886 | C2: 282330 | D2: 비제조/서비스업 | E2: 종합 소매업 | F2: 체인화 편의점 | G2: 43077 | H2: 12월 | I2: 이건준 | J2: http://www.bgfretail.com | K2: 서울특별시 | L2: 2857090834 | M2: 1925834121 | N2: 931256713 | O2: 7577772993 | P2: 249222456 | Q2: 250446471 | R2: 190700183 | S2: 17283906 | T2: 8891 | U2: 5185172 | V2: =1271876+547071+921322+709646+251893+242825+2329 -> 3946962 | W2: =179820+11162+4360+1050+174+3558+1000+100 -> 201224 | X2: =1799+1798 -> 3597 | Y2: (재)홍진기 법률연구재단; (재)비지에프복지재단 | Z2: 0 | AA2: 0 | AB2: =SUM(U2,V2,Z2,W2,X2) -> 9336955 | AC2: =(AB2/S2)*100 -> 54.021093 | AD2: =100-(75*(AC2-0.1))/(87-0.1) -> 53.462808 | AE2: =AD2*0.03 -> 1.6038842 | AF2: =(U2+V2)/(S2-T2-AA2)*100 -> 52.863248 | AG2: =(U2+V2+Z2+W2+X2-AA2)/(S2-T2-AA2)*100 -> 54.048897 | AH2: =AG2-AF2 -> 1.1856488 | AI2: =IF(AH2<10, 100, IF(AH2<30, 80, IF(AH2<50, 60, IF(AH2<80, 40, IF(AH2<=100, 20))))) -> 100 | AJ2: =AI2*0.04 -> 4 | AK2: 7 | AL2: 22 | AM2: 1 | AN2: =SUM(AK2:AL2) -> 29 | AO2: =(AM2/AN2)*100 -> 3.4482759 | AP2: =IF(AO2<10, 100, IF(AO2<20, 80, IF(AO2<30, 60, IF(AO2<50, 40, IF(AO2>=50, 20))))) -> 100 | AQ2: =AP2*0.02 -> 2 | AR2: 5 | AS2: =IF(L2>=2000000000, 0.5, IF(L2<2000000000, 0.25)) -> 0.5 | AT2: =AK2*AS2 -> 3.5 | AU2: =ROUNDDOWN(AT2,0) -> 3 | AV2: =(AR2-AU2)/AK2*100 -> 28.571429 | AW2: =IF(AV2<0, 20, IF(AV2=0, 40, IF(AV2<20, 60, IF(AV2<40, 80, IF(AV2>=40, 100))))) -> 80 | AX2: =AW2*0.01 -> 0.8 | AY2: 11 | AZ2: =4*3+5*6+4*2 -> 50 | BA2: =AR2*AY2 -> 55 | BB2: =(AZ2/BA2)*100 -> 90.909091 | BC2: =IF(BB2<70, 25, IF(BB2<80, 50, IF(BB2<90, 75, IF(BB2>=90, 100)))) -> 100 | BD2: =BC2*0.01 -> 1 | BE2: 158631000 | BF2: 11401000 | BG2: 0 | BH2: =SUM(BE2:BF2) -> 170032000 | BI2: =(BG2/BH2)*100 -> 0 | BJ2: =IF(D2="금융업(보험)", "금융업", IF(D2="금융업(증권)", "금융업", IF(D2="금융업(종금)", "금융업", D2))) -> 비제조/서비스업 | BK2: =AVERAGEIF(BJ:BJ, BJ2, BI:BI) -> 1.7464435 | BL2: =BI2-BK2 -> -1.7464435 | BM2: =IF(BL2<-2, 100, IF(BL2<0, 80, IF(BL2<2, 60, IF(BL2<10, 40, 20)))) -> 80 | BN2: =BM2*0.02 -> 1.6 | BO2: 9843000 | BP2: =(BO2/O2)*100 -> 0.12989304 | BQ2: =IF(BP2=0, 25, IF(BP2<0.1, 40, IF(BP2<0.5, 55, IF(BP2<2, 70, IF(BP2<4, 85, IF(BP2>=4, 100)))))) -> 55 | BR2: =BQ2*0.02 -> 1.1 | BS2: 2.1126308e+08 | BT2: 549918.29 | BU2: =BS2-BT2 -> 2.1071316e+08 | BV2: =BU2/O2*100 -> 2.780674 | BW2: =AVERAGEIF(BJ:BJ, BJ2, BV:BV) -> 2.8482825 | BX2: =(BV2-BW2)^2 -> 0.0045709171 | BY2: =SQRT(SUMIF(BJ:BJ, BJ2, BX:BX)/COUNTIF(BJ:BJ, BJ2)) -> 5.5697596 | BZ2: =(1-_xlfn.NORM.DIST(BV2, BW2, BY2, TRUE))*100 -> 50.484244 | CA2: =IF(BZ2<=5, 100, IF(BZ2<=15, 85, IF(BZ2<=35, 70, IF(BZ2<=60, 55, IF(BZ2<=90, 40, 25))))) -> 55 | CB2: =CA2*0.02 -> 1.1 | CC2: =(M2/N2)*100 -> 206.79949 | CD2: =IF((100-(75*(CC2-1)/(200-1)))>100, 100, IF((100-(75*(CC2-1)/(200-1)))<25, 25, (100-(75*(CC2-1)/(200-1))))) -> 25 | CE2: =CD2*0.015 -> 0.375 | CF2: 평가제외 | CG2: 평가제외 | CH2: 평가제외 | CI2: 평가제외 | CK2: AA | CL2: B | CM2: =IF(CL2="A", 100, IF(CL2="B", 85, IF(CL2="C", 70, IF(CL2="D", 55, IF(CL2="E", 40, 25))))) -> 85 | CN2: =CM2*0.015 -> 1.275 | CO2: =39104000+33584000+3302000 -> 75990000 | CP2: =(CO2/N2)*100 -> 8.1599412 | CQ2: =IF(CP2<3, 100, IF(CP2<10, 80, IF(CP2<35, 60, IF(CP2<100, 40, IF(CP2>=100, 20))))) -> 80 | CR2: =CQ2*0.03 -> 2.4 | CS2: =_xlfn.XLOOKUP(C2, '1-1. 관계사체무보증금액 (환율 등)'!$3:$3, '1-1. 관계사체무보증금액 (환율 등)'!$33:$33) -> 11092000 | CT2: =(CS2/N2)*100 -> 1.1910787 | CU2: =IF(CT2<3, 100, IF(CT2<10, 80, IF(CT2<35, 60, IF(CT2<100, 40, 20)))) -> 100 | CV2: =CU2*0.02 -> 2 | CW2: =AE2+AJ2+AQ2+AX2+BD2+BN2+BR2+CB2+CE2+CJ2+CN2+CR2+CV2 -> 19.253884
A3: BYC | B3: https://dart.fss.or.kr/dsaf001/main.do?rcpNo=20230316001312 | C3: 001460 | D3: 식약/섬유/종이업 | E3: 봉제의복 제조업 | F3: 메리야스,란제리 제조,도매/건축공사/부동산 임대,분양,공급 | G3: 27547 | H3: 12월 | I3: 김 대 환 | J3: http://home.byc.co.kr | K3: 서울특별시 | L3: 657344581 | M3: 145796846 | N3: 511547734 | O3: 168169259 | P3: 24457946 | Q3: 48325988 | R3: 35650140 | S3: 624615 | T3: 8 | U3: 115140 | V3: =46328+28126+21560+23065+20 -> 119099 | W3: =25621+560+20+32+195+25 -> 26453 | X3: 31230 | Y3: 신한학원 | Z3: =65873+1906+18739+16002+34+128 -> 102682 | AA3: 0 | AB3: =SUM(U3,V3,Z3,W3,X3) -> 394604 | AC3: =(AB3/S3)*100 -> 63.175556 | AD3: =100-(75*(AC3-0.1))/(87-0.1) -> 45.561948 | AE3: =AD3*0.03 -> 1.3668584 | AF3: =(U3+V3)/(S3-T3-AA3)*100 -> 37.501821 | AG3: =(U3+V3+Z3+W3+X3-AA3)/(S3-T3-AA3)*100 -> 63.176365 | AH3: =AG3-AF3 -> 25.674544 | AI3: =IF(AH3<10, 100, IF(AH3<30, 80, IF(AH3<50, 60, IF(AH3<80, 40, IF(AH3<=100, 20))))) -> 80 | AJ3: =AI3*0.04 -> 3.2 | AK3: 6 | AL3: 6 | AM3: 5 | AN3: =SUM(AK3:AL3) -> 12 | AO3: =(AM3/AN3)*100 -> 41.666667 | AP3: =IF(AO3<10, 100, IF(AO3<20, 80, IF(AO3<30, 60, IF(AO3<50, 40, IF(AO3>=50, 20))))) -> 40 | AQ3: =AP3*0.02 -> 0.8 | AR3: 3 | AS3: =IF(L3>=2000000000, 0.5, IF(L3<2000000000, 0.25)) -> 0.25 | AT3: =AK3*AS3 -> 1.5 | AU3: =ROUNDDOWN(AT3,0) -> 1 | AV3: =(AR3-AU3)/AK3*100 -> 33.333333 | AW3: =IF(AV3<0, 20, IF(AV3=0, 40, IF(AV3<20, 60, IF(AV3<40, 80, IF(AV3>=40, 100))))) -> 80 | AX3: =AW3*0.01 -> 0.8 | AY3: 8 | AZ3: =3*5+2*3 -> 21 | BA3: =AR3*AY3 -> 24 | BB3: =(AZ3/BA3)*100 -> 87.5 | BC3: =IF(BB3<70, 25, IF(BB3<80, 50, IF(BB3<90, 75, IF(BB3>=90, 100)))) -> 75 | BD3: =BC3*0.01 -> 0.75 | BE3: 19793253 | BF3: 1476274.3 | BG3: 72540.59 | BH3: =SUM(BE3:BF3) -> 21269527 | BI3: =(BG3/BH3)*100 -> 0.34105408 | BJ3: =IF(D3="금융업(보험)", "금융업", IF(D3="금융업(증권)", "금융업", IF(D3="금융업(종금)", "금융업", D3))) -> 식약/섬유/종이업 | BK3: =AVERAGEIF(BJ:BJ, BJ3, BI:BI) -> 2.1999361 | BL3: =BI3-BK3 -> -1.858882 | BM3: =IF(BL3<-2, 100, IF(BL3<0, 80, IF(BL3<2, 60, IF(BL3<10, 40, 20)))) -> 80 | BN3: =BM3*0.02 -> 1.6 | BO3: 1294493 | BP3: =(BO3/O3)*100 -> 0.76975602 | BQ3: =IF(BP3=0, 25, IF(BP3<0.1, 40, IF(BP3<0.5, 55, IF(BP3<2, 70, IF(BP3<4, 85, IF(BP3>=4, 100)))))) -> 70 | BR3: =BQ3*0.02 -> 1.4 | BS3: 9625686.4 | BT3: 852363.59 | BU3: =BS3-BT3 -> 8773322.8 | BV3: =BU3/O3*100 -> 5.2169599 | BW3: =AVERAGEIF(BJ:BJ, BJ3, BV:BV) -> 5.0508176 | BX3: =(BV3-BW3)^2 -> 0.027603266 | BY3: =SQRT(SUMIF(BJ:BJ, BJ3, BX:BX)/COUNTIF(BJ:BJ, BJ3)) -> 6.9871618 | BZ3: =(1-_xlfn.NORM.DIST(BV3, BW3, BY3, TRUE))*100 -> 49.051475 | CA3: =IF(BZ3<=5, 100, IF(BZ3<=15, 85, IF(BZ3<=35, 70, IF(BZ3<=60, 55, IF(BZ3<=90, 40, 25))))) -> 55 | CB3: =CA3*0.02 -> 1.1 | CC3: =(M3/N3)*100 -> 28.501122 | CD3: =IF((100-(75*(CC3-1)/(200-1)))>100, 100, IF((100-(75*(CC3-1)/(200-1)))<25, 25, (100-(75*(CC3-1)/(200-1))))) -> 89.635255 | CE3: =CD3*0.015 -> 1.3445288 | CF3: 평가제외 | CG3: 평가제외 | CH3: 평가제외 | CI3: 평가제외 | CK3: 미공시 | CL3: F | CM3: =IF(CL3="A", 100, IF(CL3="B", 85, IF(CL3="C", 70, IF(CL3="D", 55, IF(CL3="E", 40, 25))))) -> 25 | CN3: =CM3*0.015 -> 0.375 | CO3: 50000 | CP3: =(CO3/N3)*100 -> 0.0097742589 | CQ3: =IF(CP3<3, 100, IF(CP3<10, 80, IF(CP3<35, 60, IF(CP3<100, 40, IF(CP3>=100, 20))))) -> 100 | CR3: =CQ3*0.03 -> 3 | CS3: =_xlfn.XLOOKUP(C3, '1-1. 관계사체무보증금액 (환율 등)'!$3:$3, '1-1. 관계사체무보증금액 (환율 등)'!$33:$33) -> 15189873 | CT3: =(CS3/N3)*100 -> 2.9693951 | CU3: =IF(CT3<3, 100, IF(CT3<10, 80, IF(CT3<35, 60, IF(CT3<100, 40, 20)))) -> 100 | CV3: =CU3*0.02 -> 2 | CW3: =AE3+AJ3+AQ3+AX3+BD3+BN3+BR3+CB3+CE3+CJ3+CN3+CR3+CV3 -> 17.736387
A4: CJ대한통운 | B4: https://dart.fss.or.kr/dsaf001/main.do?rcpNo=20230317000857 | C4: 000120 | D4: 비제조/서비스업 | E4: 도로 화물 운송업 | F4: Contract Logistics, 포워딩, 항만하역, 해운, 택배국제특송, SCM Consulting | G4: 20638 | H4: 12월 | I4: 강신호,민영학(각자대표) | J4: http://www.cjlogistics.com | K4: 서울특별시 | L4: 7825113458 | M4: 4398363795 | N4: 3426749663 | O4: 8214653866 | P4: 262723385 | Q4: 247777952 | R4: 200576209 | S4: 22812344 | T4: 2867456 | U4: 9162522 | V4: 0 | W4: =800+2000 -> 2800 | X4: 0 | Z4: 0 | AA4: 0 | AB4: =SUM(U4,V4,Z4,W4,X4) -> 9165322 | AC4: =(AB4/S4)*100 -> 40.177029 | AD4: =100-(75*(AC4-0.1))/(87-0.1) -> 65.41108 | AE4: =AD4*0.03 -> 1.9623324 | AF4: =(U4+V4)/(S4-T4-AA4)*100 -> 45.9392 | AG4: =(U4+V4+Z4+W4+X4-AA4)/(S4-T4-AA4)*100 -> 45.953239 | AH4: =AG4-AF4 -> 0.014038685 | AI4: =IF(AH4<10, 100, IF(AH4<30, 80, IF(AH4<50, 60, IF(AH4<80, 40, IF(AH4<=100, 20))))) -> 100 | AJ4: =AI4*0.04 -> 4 | AK4: 7 | AL4: 66 | AM4: 0 | AN4: =SUM(AK4:AL4) -> 73 | AO4: =(AM4/AN4)*100 -> 0 | AP4: =IF(AO4<10, 100, IF(AO4<20, 80, IF(AO4<30, 60, IF(AO4<50, 40, IF(AO4>=50, 20))))) -> 100 | AQ4: =AP4*0.02 -> 2 | AR4: 4 | AS4: =IF(L4>=2000000000, 0.5, IF(L4<2000000000, 0.25)) -> 0.5 | AT4: =AK4*AS4 -> 3.5 | AU4: =ROUNDDOWN(AT4,0) -> 3 | AV4: =(AR4-AU4)/AK4*100 -> 14.285714 | AW4: =IF(AV4<0, 20, IF(AV4=0, 40, IF(AV4<20, 60, IF(AV4<40, 80, IF(AV4>=40, 100))))) -> 60 | AX4: =AW4*0.01 -> 0.6 | AY4: 8 | AZ4: 32 | BA4: =AR4*AY4 -> 32 | BB4: =(AZ4/BA4)*100 -> 100 | BC4: =IF(BB4<70, 25, IF(BB4<80, 50, IF(BB4<90, 75, IF(BB4>=90, 100)))) -> 100 | BD4: =BC4*0.01 -> 1 | BE4: 186921979 | BF4: 15773356 | BG4: 4026318 | BH4: =SUM(BE4:BF4) -> 202695335 | BI4: =(BG4/BH4)*100 -> 1.9863891 | BJ4: =IF(D4="금융업(보험)", "금융업", IF(D4="금융업(증권)", "금융업", IF(D4="금융업(종금)", "금융업", D4))) -> 비제조/서비스업 | BK4: =AVERAGEIF(BJ:BJ, BJ4, BI:BI) -> 1.7464435 | BL4: =BI4-BK4 -> 0.23994562 | BM4: =IF(BL4<-2, 100, IF(BL4<0, 80, IF(BL4<2, 60, IF(BL4<10, 40, 20)))) -> 60 | BN4: =BM4*0.02 -> 1.2 | BO4: 0 | BP4: =(BO4/O4)*100 -> 0 | BQ4: =IF(BP4=0, 25, IF(BP4<0.1, 40, IF(BP4<0.5, 55, IF(BP4<2, 70, IF(BP4<4, 85, IF(BP4>=4, 100)))))) -> 25 | BR4: =BQ4*0.02 -> 0.5 | BS4: 2.0740612e+08 | BT4: 13646107 | BU4: =BS4-BT4 -> 1.9376002e+08 | BV4: =BU4/O4*100 -> 2.3587119 | BW4: =AVERAGEIF(BJ:BJ, BJ4, BV:BV) -> 2.8482825 | BX4: =(BV4-BW4)^2 -> 0.23967942 | BY4: =SQRT(SUMIF(BJ:BJ, BJ4, BX:BX)/COUNTIF(BJ:BJ, BJ4)) -> 5.5697596 | BZ4: =(1-_xlfn.NORM.DIST(BV4, BW4, BY4, TRUE))*100 -> 53.502112 | CA4: =IF(BZ4<=5, 100, IF(BZ4<=15, 85, IF(BZ4<=35, 70, IF(BZ4<=60, 55, IF(BZ4<=90, 40, 25))))) -> 55 | CB4: =CA4*0.02 -> 1.1 | CC4: =(M4/N4)*100 -> 128.35381 | CD4: =IF((100-(75*(CC4-1)/(200-1)))>100, 100, IF((100-(75*(CC4-1)/(200-1)))<25, 25, (100-(75*(CC4-1)/(200-1))))) -> 52.002332 | CE4: =CD4*0.015 -> 0.78003499 | CF4: 평가제외 | CG4: 평가제외 | CH4: 평가제외 | CI4: 평가제외 | CK4: A1, AA- | CL4: B | CM4: =IF(CL4="A", 100, IF(CL4="B", 85, IF(CL4="C", 70, IF(CL4="D", 55, IF(CL4="E", 40, 25))))) -> 85 | CN4: =CM4*0.015 -> 1.275 | CO4: =220400+326898+11698303+5000000+248288906+9299119+76869504+138402431+1443622+35330+10037884+111951016+57778363+65159018 -> 736510794 | CP4: =(CO4/N4)*100 -> 21.492985 | CQ4: =IF(CP4<3, 100, IF(CP4<10, 80, IF(CP4<35, 60, IF(CP4<100, 40, IF(CP4>=100, 20))))) -> 60 | CR4: =CQ4*0.03 -> 1.8 | CS4: =_xlfn.XLOOKUP(C4, '1-1. 관계사체무보증금액 (환율 등)'!$3:$3, '1-1. 관계사체무보증금액 (환율 등)'!$33:$33) -> 75200000 | CT4: =(CS4/N4)*100 -> 2.1944994 | CU4: =IF(CT4<3, 100, IF(CT4<10, 80, IF(CT4<35, 60, IF(CT4<100, 40, 20)))) -> 100 | CV4: =CU4*0.02 -> 2 | CW4: =AE4+AJ4+AQ4+AX4+BD4+BN4+BR4+CB4+CE4+CJ4+CN4+CR4+CV4 -> 18.217367
A5: CJ씨푸드 | B5: https://dart.fss.or.kr/dsaf001/main.do?rcpNo=20230320000740 | C5: 011150 | D5: 식약/섬유/종이업 | E5: 기타 식품 제조업 | F5: 수산물(어묵,맛살)가공품 도매,원양수산업,수출입 | G5: 32473 | H5: 12월 | I5: 김정웅, 박태준(각자대표) | J5: http://www.cjseafood.net | K5: 경기도 | L5: 143409087 | M5: 67719807 | N5: 75689279 | O5: 152701472 | P5: 4135028 | Q5: 6675009 | R5: 7419861 | S5: =35931*1000 -> 35931000 | T5: 0 | U5: =16714*1000 -> 16714000 | V5: 0 | W5: 0 | X5: 0 | Z5: 0 | AA5: 0 | AB5: =SUM(U5,V5,Z5,W5,X5) -> 16714000 | AC5: =(AB5/S5)*100 -> 46.516935 | AD5: =100-(75*(AC5-0.1))/(87-0.1) -> 59.939354 | AE5: =AD5*0.03 -> 1.7981806 | AF5: =(U5+V5)/(S5-T5-AA5)*100 -> 46.516935 | AG5: =(U5+V5+Z5+W5+X5-AA5)/(S5-T5-AA5)*100 -> 46.516935 | AH5: =AG5-AF5 -> 0 | AI5: =IF(AH5<10, 100, IF(AH5<30, 80, IF(AH5<50, 60, IF(AH5<80, 40, IF(AH5<=100, 20))))) -> 100 | AJ5: =AI5*0.04 -> 4 | AK5: 4 | AL5: 1 | AM5: 0 | AN5: =SUM(AK5:AL5) -> 5 | AO5: =(AM5/AN5)*100 -> 0 | AP5: =IF(AO5<10, 100, IF(AO5<20, 80, IF(AO5<30, 60, IF(AO5<50, 40, IF(AO5>=50, 20))))) -> 100 | AQ5: =AP5*0.02 -> 2 | AR5: 1 | AS5: =IF(L5>=2000000000, 0.5, IF(L5<2000000000, 0.25)) -> 0.25 | AT5: =AK5*AS5 -> 1 | AU5: =ROUNDDOWN(AT5,0) -> 1 | AV5: =(AR5-AU5)/AK5*100 -> 0 | AW5: =IF(AV5<0, 20, IF(AV5=0, 40, IF(AV5<20, 60, IF(AV5<40, 80, IF(AV5>=40, 100))))) -> 40 | AX5: =AW5*0.01 -> 0.4 | AY5: 13 | AZ5: 13 | BA5: =AR5*AY5 -> 13 | BB5: =(AZ5/BA5)*100 -> 100 | BC5: =IF(BB5<70, 25, IF(BB5<80, 50, IF(BB5<90, 75, IF(BB5>=90, 100)))) -> 100 | BD5: =BC5*0.01 -> 1 | BE5: 4489654 | BF5: 404120 | BG5: 0 | BH5: =SUM(BE5:BF5) -> 4893774 | BI5: =(BG5/BH5)*100 -> 0 | BJ5: =IF(D5="금융업(보험)", "금융업", IF(D5="금융업(증권)", "금융업", IF(D5="금융업(종금)", "금융업", D5))) -> 식약/섬유/종이업 | BK5: =AVERAGEIF(BJ:BJ, BJ5, BI:BI) -> 2.1999361 | BL5: =BI5-BK5 -> -2.1999361 | BM5: =IF(BL5<-2, 100, IF(BL5<0, 80, IF(BL5<2, 60, IF(BL5<10, 40, 20)))) -> 100 | BN5: =BM5*0.02 -> 2 | BO5: 141974 | BP5: =(BO5/O5)*100 -> 0.092974873 | BQ5: =IF(BP5=0, 25, IF(BP5<0.1, 40, IF(BP5<0.5, 55, IF(BP5<2, 70, IF(BP5<4, 85, IF(BP5>=4, 100)))))) -> 40 | BR5: =BQ5*0.02 -> 0.8 | BS5: 2249707 | BT5: 262842 | BU5: =BS5-BT5 -> 1986865 | BV5: =BU5/O5*100 -> 1.3011433 | BW5: =AVERAGEIF(BJ:BJ, BJ5, BV:BV) -> 5.0508176 | BX5: =(BV5-BW5)^2 -> 14.060057 | BY5: =SQRT(SUMIF(BJ:BJ, BJ5, BX:BX)/COUNTIF(BJ:BJ, BJ5)) -> 6.9871618 | BZ5: =(1-_xlfn.NORM.DIST(BV5, BW5, BY5, TRUE))*100 -> 70.424599 | CA5: =IF(BZ5<=5, 100, IF(BZ5<=15, 85, IF(BZ5<=35, 70, IF(BZ5<=60, 55, IF(BZ5<=90, 40, 25))))) -> 40 | CB5: =CA5*0.02 -> 0.8 | CC5: =(M5/N5)*100 -> 89.470805 | CD5: =IF((100-(75*(CC5-1)/(200-1)))>100, 100, IF((100-(75*(CC5-1)/(200-1)))<25, 25, (100-(75*(CC5-1)/(200-1))))) -> 66.656732 | CE5: =CD5*0.015 -> 0.99985098 | CF5: 평가제외 | CG5: 평가제외 | CH5: 평가제외 | CI5: 평가제외 | CK5: A- | CL5: D | CM5: =IF(CL5="A", 100, IF(CL5="B", 85, IF(CL5="C", 70, IF(CL5="D", 55, IF(CL5="E", 40, 25))))) -> 55 | CN5: =CM5*0.015 -> 0.825 | CO5: 0 | CP5: =(CO5/N5)*100 -> 0 | CQ5: =IF(CP5<3, 100, IF(CP5<10, 80, IF(CP5<35, 60, IF(CP5<100, 40, IF(CP5>=100, 20))))) -> 100 | CR5: =CQ5*0.03 -> 3 | CS5: =_xlfn.XLOOKUP(C5, '1-1. 관계사체무보증금액 (환율 등)'!$3:$3, '1-1. 관계사체무보증금액 (환율 등)'!$33:$33) -> 0 | CT5: =(CS5/N5)*100 -> 0 | CU5: =IF(CT5<3, 100, IF(CT5<10, 80, IF(CT5<35, 60, IF(CT5<100, 40, 20)))) -> 100 | CV5: =CU5*0.02 -> 2 | CW5: =AE5+AJ5+AQ5+AX5+BD5+BN5+BR5+CB5+CE5+CJ5+CN5+CR5+CV5 -> 19.623032
A6: CJ제일제당 | B6: https://dart.fss.or.kr/dsaf001/main.do?rcpNo=20230814001661 | C6: 097950 | D6: 식약/섬유/종이업 | E6: 기타 식품 제조업 | F6: 설탕,소맥분,조미식품,육가공식품(돈육,돼지비계,돼지식용설육),대두가공식품,사료,의약품,생활화학제품 제조,도매,무역/통신판매 | G6: 39353 | H6: 12월 | I6: 손경식, 최은석 (각자 대표이사) | J6: http://www.cj.co.kr | K6: 서울특별시 | L6: 11450867716 | M6: 6158689194 | N6: 5292178522 | O6: 7842662871 | P6: 405033974 | Q6: 333649782 | R6: 265820089 | S6: 15054186 | T6: 357303 | U6: 6707016 | V6: =70931+22015 -> 92946 | W6: =5491 -> 5491 | X6: =30351+7844 -> 38195 | Y6: CJ나눔재단; CJ문화재단 | Z6: 0 | AA6: 0 | AB6: =SUM(U6,V6,Z6,W6,X6) -> 6843648 | AC6: =(AB6/S6)*100 -> 45.4601 | AD6: =100-(75*(AC6-0.1))/(87-0.1) -> 60.851467 | AE6: =AD6*0.03 -> 1.825544 | AF6: =(U6+V6)/(S6-T6-AA6)*100 -> 46.268056 | AG6: =(U6+V6+Z6+W6+X6-AA6)/(S6-T6-AA6)*100 -> 46.565302 | AH6: =AG6-AF6 -> 0.2972467 | AI6: =IF(AH6<10, 100, IF(AH6<30, 80, IF(AH6<50, 60, IF(AH6<80, 40, IF(AH6<=100, 20))))) -> 100 | AJ6: =AI6*0.04 -> 4 | AK6: 7 | AL6: 124 | AM6: 1 | AN6: =SUM(AK6:AL6) -> 131 | AO6: =(AM6/AN6)*100 -> 0.76335878 | AP6: =IF(AO6<10, 100, IF(AO6<20, 80, IF(AO6<30, 60, IF(AO6<50, 40, IF(AO6>=50, 20))))) -> 100 | AQ6: =AP6*0.02 -> 2 | AR6: 4 | AS6: =IF(L6>=2000000000, 0.5, IF(L6<2000000000, 0.25)) -> 0.5 | AT6: =AK6*AS6 -> 3.5 | AU6: =ROUNDDOWN(AT6,0) -> 3 | AV6: =(AR6-AU6)/AK6*100 -> 14.285714 | AW6: =IF(AV6<0, 20, IF(AV6=0, 40, IF(AV6<20, 60, IF(AV6<40, 80, IF(AV6>=40, 100))))) -> 60 | AX6: =AW6*0.01 -> 0.6 | AY6: 10 | AZ6: =3*10+9 -> 39 | BA6: =AR6*AY6 -> 40 | BB6: =(AZ6/BA6)*100 -> 97.5 | BC6: =IF(BB6<70, 25, IF(BB6<80, 50, IF(BB6<90, 75, IF(BB6>=90, 100)))) -> 100 | BD6: =BC6*0.01 -> 1 | BE6: 413644637 | BF6: 35354329 | BG6: 0 | BH6: =SUM(BE6:BF6) -> 448998966 | BI6: =(BG6/BH6)*100 -> 0 | BJ6: =IF(D6="금융업(보험)", "금융업", IF(D6="금융업(증권)", "금융업", IF(D6="금융업(종금)", "금융업", D6))) -> 식약/섬유/종이업 | BK6: =AVERAGEIF(BJ:BJ, BJ6, BI:BI) -> 2.1999361 | BL6: =BI6-BK6 -> -2.1999361 | BM6: =IF(BL6<-2, 100, IF(BL6<0, 80, IF(BL6<2, 60, IF(BL6<10, 40, 20)))) -> 100 | BN6: =BM6*0.02 -> 2 | BO6: 218745000 | BP6: =(BO6/O6)*100 -> 2.7891674 | BQ6: =IF(BP6=0, 25, IF(BP6<0.1, 40, IF(BP6<0.5, 55, IF(BP6<2, 70, IF(BP6<4, 85, IF(BP6>=4, 100)))))) -> 85 | BR6: =BQ6*0.02 -> 1.7 | BS6: 213596218 | BT6: 6644041 | BU6: =BS6-BT6 -> 206952177 | BV6: =BU6/O6*100 -> 2.6387999 | BW6: =AVERAGEIF(BJ:BJ, BJ6, BV:BV) -> 5.0508176 | BX6: =(BV6-BW6)^2 -> 5.8178296 | BY6: =SQRT(SUMIF(BJ:BJ, BJ6, BX:BX)/COUNTIF(BJ:BJ, BJ6)) -> 6.9871618 | BZ6: =(1-_xlfn.NORM.DIST(BV6, BW6, BY6, TRUE))*100 -> 63.503065 | CA6: =IF(BZ6<=5, 100, IF(BZ6<=15, 85, IF(BZ6<=35, 70, IF(BZ6<=60, 55, IF(BZ6<=90, 40, 25))))) -> 40 | CB6: =CA6*0.02 -> 0.8 | CC6: =(M6/N6)*100 -> 116.37342 | CD6: =IF((100-(75*(CC6-1)/(200-1)))>100, 100, IF((100-(75*(CC6-1)/(200-1)))<25, 25, (100-(75*(CC6-1)/(200-1))))) -> 56.517555 | CE6: =CD6*0.015 -> 0.84776332 | CF6: 평가제외 | CG6: 평가제외 | CH6: 평가제외 | CI6: 평가제외 | CK6: A1, AA | CL6: A | CM6: =IF(CL6="A", 100, IF(CL6="B", 85, IF(CL6="C", 70, IF(CL6="D", 55, IF(CL6="E", 40, 25))))) -> 100 | CN6: =CM6*0.015 -> 1.5 | CO6: =19995000+1528234000+789000+10498000+8613000+277765000+74825000+56786000+127807000+158000+150000+76552000+8483000+564000+162933000+260605000+6536000+8452000+16449000+1791000+238077000+10825000+1485232000+48507000+59894000+14387000+184000+208455000 -> 4713546000 | CP6: =(CO6/N6)*100 -> 89.06627 | CQ6: =IF(CP6<3, 100, IF(CP6<10, 80, IF(CP6<35, 60, IF(CP6<100, 40, IF(CP6>=100, 20))))) -> 40 | CR6: =CQ6*0.03 -> 1.2 | CS6: =_xlfn.XLOOKUP(C6, '1-1. 관계사체무보증금액 (환율 등)'!$3:$3, '1-1. 관계사체무보증금액 (환율 등)'!$33:$33) -> 5.2685813e+09 | CT6: =(CS6/N6)*100 -> 99.554112 | CU6: =IF(CT6<3, 100, IF(CT6<10, 80, IF(CT6<35, 60, IF(CT6<100, 40, 20)))) -> 40 | CV6: =CU6*0.02 -> 0.8 | CW6: =AE6+AJ6+AQ6+AX6+BD6+BN6+BR6+CB6+CE6+CJ6+CN6+CR6+CV6 -> 18.273307
A7: DB | B7: https://dart.fss.or.kr/dsaf001/main.do?rcpNo=20230321001132 | C7: 012030 | D7: 비제조/서비스업 | E7: 컴퓨터 프로그래밍, 시스템 통합 및 관리업 | F7: 컴퓨터 프로그래밍, 시스템 통합 및 관리 | G7: 33975 | H7: 12월 | I7: 문덕식,강운식 (각자 대표이사) | J7: http://www.dbinc.co.kr | K7: 서울특별시 | L7: 428747549 | M7: 121241747 | N7: 307505802 | O7: 347588559 | P7: 12401397 | Q7: 14089238 | R7: 10922265 | S7: 201173933 | T7: 10143400 | U7: 33856750 | V7: =31997041+19861669+141160+286650+647910+573330+286650+120000+64580+37290+149160 -> 54165440 | W7: =7000+175500+7030+23540+10000 -> 223070 | X7: 0 | Z7: 0 | AA7: 0 | AB7: =SUM(U7,V7,Z7,W7,X7) -> 88245260 | AC7: =(AB7/S7)*100 -> 43.865156 | AD7: =100-(75*(AC7-0.1))/(87-0.1) -> 62.228001 | AE7: =AD7*0.03 -> 1.86684 | AF7: =(U7+V7)/(S7-T7-AA7)*100 -> 46.07755 | AG7: =(U7+V7+Z7+W7+X7-AA7)/(S7-T7-AA7)*100 -> 46.194322 | AH7: =AG7-AF7 -> 0.11677191 | AI7: =IF(AH7<10, 100, IF(AH7<30, 80, IF(AH7<50, 60, IF(AH7<80, 40, IF(AH7<=100, 20))))) -> 100 | AJ7: =AI7*0.04 -> 4 | AK7: 6 | AL7: 12 | AM7: 3 | AN7: =SUM(AK7:AL7) -> 18 | AO7: =(AM7/AN7)*100 -> 16.666667 | AP7: =IF(AO7<10, 100, IF(AO7<20, 80, IF(AO7<30, 60, IF(AO7<50, 40, IF(AO7>=50, 20))))) -> 80 | AQ7: =AP7*0.02 -> 1.6 | AR7: 3 | AS7: =IF(L7>=2000000000, 0.5, IF(L7<2000000000, 0.25)) -> 0.25 | AT7: =AK7*AS7 -> 1.5 | AU7: =ROUNDDOWN(AT7,0) -> 1 | AV7: =(AR7-AU7)/AK7*100 -> 33.333333 | AW7: =IF(AV7<0, 20, IF(AV7=0, 40, IF(AV7<20, 60, IF(AV7<40, 80, IF(AV7>=40, 100))))) -> 80 | AX7: =AW7*0.01 -> 0.8 | AY7: 5 | AZ7: 15 | BA7: =AR7*AY7 -> 15 | BB7: =(AZ7/BA7)*100 -> 100 | BC7: =IF(BB7<70, 25, IF(BB7<80, 50, IF(BB7<90, 75, IF(BB7>=90, 100)))) -> 100 | BD7: =BC7*0.01 -> 1 | BE7: 34040504 | BF7: 2466355 | BG7: 0 | BH7: =SUM(BE7:BF7) -> 36506859 | BI7: =(BG7/BH7)*100 -> 0 | BJ7: =IF(D7="금융업(보험)", "금융업", IF(D7="금융업(증권)", "금융업", IF(D7="금융업(종금)", "금융업", D7))) -> 비제조/서비스업 | BK7: =AVERAGEIF(BJ:BJ, BJ7, BI:BI) -> 1.7464435 | BL7: =BI7-BK7 -> -1.7464435 | BM7: =IF(BL7<-2, 100, IF(BL7<0, 80, IF(BL7<2, 60, IF(BL7<10, 40, 20)))) -> 80 | BN7: =BM7*0.02 -> 1.6 | BO7: 0 | BP7: =(BO7/O7)*100 -> 0 | BQ7: =IF(BP7=0, 25, IF(BP7<0.1, 40, IF(BP7<0.5, 55, IF(BP7<2, 70, IF(BP7<4, 85, IF(BP7>=4, 100)))))) -> 25 | BR7: =BQ7*0.02 -> 0.5 | BS7: 666066.11 | BT7: 5203 | BU7: =BS7-BT7 -> 660863.11 | BV7: =BU7/O7*100 -> 0.19012798 | BW7: =AVERAGEIF(BJ:BJ, BJ7, BV:BV) -> 2.8482825 | BX7: =(BV7-BW7)^2 -> 7.0657857 | BY7: =SQRT(SUMIF(BJ:BJ, BJ7, BX:BX)/COUNTIF(BJ:BJ, BJ7)) -> 5.5697596 | BZ7: =(1-_xlfn.NORM.DIST(BV7, BW7, BY7, TRUE))*100 -> 68.34071 | CA7: =IF(BZ7<=5, 100, IF(BZ7<=15, 85, IF(BZ7<=35, 70, IF(BZ7<=60, 55, IF(BZ7<=90, 40, 25))))) -> 40 | CB7: =CA7*0.02 -> 0.8 | CC7: =(M7/N7)*100 -> 39.427466 | CD7: =IF((100-(75*(CC7-1)/(200-1)))>100, 100, IF((100-(75*(CC7-1)/(200-1)))<25, 25, (100-(75*(CC7-1)/(200-1))))) -> 85.517287 | CE7: =CD7*0.015 -> 1.2827593 | CF7: 평가제외 | CG7: 평가제외 | CH7: 평가제외 | CI7: 평가제외 | CK7: 미평가 | CL7: F | CM7: =IF(CL7="A", 100, IF(CL7="B", 85, IF(CL7="C", 70, IF(CL7="D", 55, IF(CL7="E", 40, 25))))) -> 25 | CN7: =CM7*0.015 -> 0.375 | CO7: 318139000 | CP7: =(CO7/N7)*100 -> 103.45789 | CQ7: =IF(CP7<3, 100, IF(CP7<10, 80, IF(CP7<35, 60, IF(CP7<100, 40, IF(CP7>=100, 20))))) -> 20 | CR7: =CQ7*0.03 -> 0.6 | CS7: =_xlfn.XLOOKUP(C7, '1-1. 관계사체무보증금액 (환율 등)'!$3:$3, '1-1. 관계사체무보증금액 (환율 등)'!$33:$33) -> 0 | CT7: =(CS7/N7)*100 -> 0 | CU7: =IF(CT7<3, 100, IF(CT7<10, 80, IF(CT7<35, 60, IF(CT7<100, 40, 20)))) -> 100 | CV7: =CU7*0.02 -> 2 | CW7: =AE7+AJ7+AQ7+AX7+BD7+BN7+BR7+CB7+CE7+CJ7+CN7+CR7+CV7 -> 16.424599
A8: DB손해보험 | B8: https://dart.fss.or.kr/dsaf001/main.do?rcpNo=20230831001199 | C8: 005830 | D8: 금융업(보험) | E8: 보험업 | F8: 자동차보험,화재보험,해상보험,특종보험,장기보험 | G8: 26843 | H8: 12월 | I8: 김정남, 정종표 | J8: http://www.idbins.com | K8: 서울특별시 | L8: 50491197385 | M8: 45440998151 | N8: 5050199234 | O8: 14569718977 | P8: 1292467004 | Q8: 1295672581 | R8: 980567336 | S8: 70800000 | T8: 10756531 | U8: 6379520 | V8: =4208500+2229640 -> 6438140 | W8: =73000+1500+210+2934+400+80+3938+500+300+200+606+1000+400+270+245+1000+55+80 -> 86718 | X8: 3539070 | Y8: DB김준기문화재단 | Z8: 0 | AA8: 0 | AB8: =SUM(U8,V8,Z8,W8,X8) -> 16443448 | AC8: =(AB8/S8)*100 -> 23.225209 | AD8: =100-(75*(AC8-0.1))/(87-0.1) -> 80.041534 | AE8: =AD8*0.04 -> 3.2016614 | AF8: =(U8+V8)/(S8-T8-AA8)*100 -> 21.347301 | AG8: =(U8+V8+Z8+W8+X8-AA8)/(S8-T8-AA8)*100 -> 27.385906 | AH8: =AG8-AF8 -> 6.0386051 | AI8: =IF(AH8<10, 100, IF(AH8<30, 80, IF(AH8<50, 60, IF(AH8<80, 40, IF(AH8<=100, 20))))) -> 100 | AJ8: =AI8*0.05 -> 5 | AK8: 5 | AL8: 58 | AM8: 0 | AN8: =SUM(AK8:AL8) -> 63 | AO8: =(AM8/AN8)*100 -> 0 | AP8: =IF(AO8<10, 100, IF(AO8<20, 80, IF(AO8<30, 60, IF(AO8<50, 40, IF(AO8>=50, 20))))) -> 100 | AQ8: =AP8*0.03 -> 3 | AR8: 3 | AS8: =IF(L8>=2000000000, 0.5, IF(L8<2000000000, 0.25)) -> 0.5 | AT8: =AK8*AS8 -> 2.5 | AU8: =ROUNDDOWN(AT8,0) -> 2 | AV8: =(AR8-AU8)/AK8*100 -> 20 | AW8: =IF(AV8<0, 20, IF(AV8=0, 40, IF(AV8<20, 60, IF(AV8<40, 80, IF(AV8>=40, 100))))) -> 80 | AX8: =AW8*0.02 -> 1.6 | AY8: 7 | AZ8: 21 | BA8: =AR8*AY8 -> 21 | BB8: =(AZ8/BA8)*100 -> 100 | BC8: =IF(BB8<70, 25, IF(BB8<80, 50, IF(BB8<90, 75, IF(BB8>=90, 100)))) -> 100 | BD8: =BC8*0.02 -> 2 | BE8: 349008000 | BF8: 20589000 | BG8: 0 | BH8: =SUM(BE8:BF8) -> 369597000 | BI8: =(BG8/BH8)*100 -> 0 | BJ8: =IF(D8="금융업(보험)", "금융업", IF(D8="금융업(증권)", "금융업", IF(D8="금융업(종금)", "금융업", D8))) -> 금융업 | BK8: =AVERAGEIF(BJ:BJ, BJ8, BI:BI) -> 2.7106886 | BL8: =BI8-BK8 -> -2.7106886 | BM8: =IF(BL8<-2, 100, IF(BL8<0, 80, IF(BL8<2, 60, IF(BL8<10, 40, 20)))) -> 100 | BN8: =BM8*0.02 -> 2 | BO8: 0 | BP8: =(BO8/O8)*100 -> 0 | BQ8: =IF(BP8=0, 25, IF(BP8<0.1, 40, IF(BP8<0.5, 55, IF(BP8<2, 70, IF(BP8<4, 85, IF(BP8>=4, 100)))))) -> 25 | BR8: =BQ8*0.01 -> 0.25 | BS8: 36062414 | BT8: 135483.57 | BU8: =BS8-BT8 -> 35926930 | BV8: =BU8/O8*100 -> 0.2465863 | BW8: =AVERAGEIF(BJ:BJ, BJ8, BV:BV) -> 0.39407896 | BX8: =(BV8-BW8)^2 -> 0.021754087 | BY8: =SQRT(SUMIF(BJ:BJ, BJ8, BX:BX)/COUNTIF(BJ:BJ, BJ8)) -> 1.5698938 | BZ8: =(1-_xlfn.NORM.DIST(BV8, BW8, BY8, TRUE))*100 -> 53.742585 | CA8: =IF(BZ8<=5, 100, IF(BZ8<=15, 85, IF(BZ8<=35, 70, IF(BZ8<=60, 55, IF(BZ8<=90, 40, 25))))) -> 55 | CB8: =CA8*0.02 -> 1.1 | CC8: 평가대상 제외 | CD8: 평가대상 제외 | CF8: 해당없음 | CG8: 해당없음 | CH8: 0.11 | CI8: =IF((100-(75*(CH8-10)/40))>100, 100, IF((100-(75*(CH8-10)/40))<25, 25, (100-(75*(CH8-10)/40)))) -> 100 | CJ8: =CI8*0.04 -> 4 | CK8: A | CL8: D | CM8: =IF(CL8="A", 100, IF(CL8="B", 85, IF(CL8="C", 70, IF(CL8="D", 55, IF(CL8="E", 40, 25))))) -> 55 | CN8: =CM8*0.03 -> 1.65 | CO8: =51529000+474045000+1000000+200000+200000+300000+108012000+23000000+848000+678000+2487000 -> 662299000 | CP8: =(CO8/N8)*100 -> 13.114314 | CQ8: =IF(CP8<3, 100, IF(CP8<10, 80, IF(CP8<35, 60, IF(CP8<100, 40, IF(CP8>=100, 20))))) -> 60 | CR8: =CQ8*0.04 -> 2.4 | CS8: =_xlfn.XLOOKUP(C8, '1-1. 관계사체무보증금액 (환율 등)'!$3:$3, '1-1. 관계사체무보증금액 (환율 등)'!$33:$33) -> 0 | CT8: =(CS8/N8)*100 -> 0 | CU8: =IF(CT8<3, 100, IF(CT8<10, 80, IF(CT8<35, 60, IF(CT8<100, 40, 20)))) -> 100 | CV8: =CU8*0.03 -> 3 | CW8: =AE8+AJ8+AQ8+AX8+BD8+BN8+BR8+CB8+CE8+CJ8+CN8+CR8+CV8 -> 29.201661
A9: DL | B9: https://dart.fss.or.kr/dsaf001/main.do?rcpNo=20230728000644 | C9: 000210 | D9: 금속/비금속/화학업 | E9: 기초 화학물질 제조업 | F9: 지주회사 | G9: 27792 | H9: 12월 | I9: 김종현 | J9: http://www.dlholdings.co.kr | K9: 서울특별시 | L9: 3649116385 | M9: 587165440 | N9: 3061950944 | O9: 223739892 | P9: 195878366 | Q9: 167506991 | R9: 146629624 | S9: 20955884 | T9: 25156 | U9: 8860723 | V9: =5505+12868+9639+21 -> 28033 | W9: 0 | X9: 194976 | Y9: (학)대림학원 | Z9: 0 | AA9: 0 | AB9: =SUM(U9,V9,Z9,W9,X9) -> 9083732 | AC9: =(AB9/S9)*100 -> 43.346928 | AD9: =100-(75*(AC9-0.1))/(87-0.1) -> 62.675263 | AE9: =AD9*0.03 -> 1.8802579 | AF9: =(U9+V9)/(S9-T9-AA9)*100 -> 42.467496 | AG9: =(U9+V9+Z9+W9+X9-AA9)/(S9-T9-AA9)*100 -> 43.399026 | AH9: =AG9-AF9 -> 0.93152995 | AI9: =IF(AH9<10, 100, IF(AH9<30, 80, IF(AH9<50, 60, IF(AH9<80, 40, IF(AH9<=100, 20))))) -> 100 | AJ9: =AI9*0.04 -> 4 | AK9: 5 | AL9: 8 | AM9: 1 | AN9: =SUM(AK9:AL9) -> 13 | AO9: =(AM9/AN9)*100 -> 7.6923077 | AP9: =IF(AO9<10, 100, IF(AO9<20, 80, IF(AO9<30, 60, IF(AO9<50, 40, IF(AO9>=50, 20))))) -> 100 | AQ9: =AP9*0.02 -> 2 | AR9: 3 | AS9: =IF(L9>=2000000000, 0.5, IF(L9<2000000000, 0.25)) -> 0.5 | AT9: =AK9*AS9 -> 2.5 | AU9: =ROUNDDOWN(AT9,0) -> 2 | AV9: =(AR9-AU9)/AK9*100 -> 20 | AW9: =IF(AV9<0, 20, IF(AV9=0, 40, IF(AV9<20, 60, IF(AV9<40, 80, IF(AV9>=40, 100))))) -> 80 | AX9: =AW9*0.01 -> 0.8 | AY9: 10 | AZ9: 30 | BA9: =AR9*AY9 -> 30 | BB9: =(AZ9/BA9)*100 -> 100 | BC9: =IF(BB9<70, 25, IF(BB9<80, 50, IF(BB9<90, 75, IF(BB9>=90, 100)))) -> 100 | BD9: =BC9*0.01 -> 1 | BE9: 9325000 | BF9: 708000 | BG9: 0 | BH9: =SUM(BE9:BF9) -> 10033000 | BI9: =(BG9/BH9)*100 -> 0 | BJ9: =IF(D9="금융업(보험)", "금융업", IF(D9="금융업(증권)", "금융업", IF(D9="금융업(종금)", "금융업", D9))) -> 금속/비금속/화학업 | BK9: =AVERAGEIF(BJ:BJ, BJ9, BI:BI) -> 3.9534119 | BL9: =BI9-BK9 -> -3.9534119 | BM9: =IF(BL9<-2, 100, IF(BL9<0, 80, IF(BL9<2, 60, IF(BL9<10, 40, 20)))) -> 100 | BN9: =BM9*0.02 -> 2 | BO9: 0 | BP9: =(BO9/O9)*100 -> 0 | BQ9: =IF(BP9=0, 25, IF(BP9<0.1, 40, IF(BP9<0.5, 55, IF(BP9<2, 70, IF(BP9<4, 85, IF(BP9>=4, 100)))))) -> 25 | BR9: =BQ9*0.02 -> 0.5 | BS9: 9294.818 | BT9: 987.367 | BU9: =BS9-BT9 -> 8307.451 | BV9: =BU9/O9*100 -> 0.003712995 | BW9: =AVERAGEIF(BJ:BJ, BJ9, BV:BV) -> 5.1474159 | BX9: =(BV9-BW9)^2 -> 26.457679 | BY9: =SQRT(SUMIF(BJ:BJ, BJ9, BX:BX)/COUNTIF(BJ:BJ, BJ9)) -> 6.6930499 | BZ9: =(1-_xlfn.NORM.DIST(BV9, BW9, BY9, TRUE))*100 -> 77.890908 | CA9: =IF(BZ9<=5, 100, IF(BZ9<=15, 85, IF(BZ9<=35, 70, IF(BZ9<=60, 55, IF(BZ9<=90, 40, 25))))) -> 40 | CB9: =CA9*0.02 -> 0.8 | CC9: =(M9/N9)*100 -> 19.176187 | CD9: =IF((100-(75*(CC9-1)/(200-1)))>100, 100, IF((100-(75*(CC9-1)/(200-1)))<25, 25, (100-(75*(CC9-1)/(200-1))))) -> 93.149678 | CE9: =CD9*0.015 -> 1.3972452 | CF9: 평가제외 | CG9: 평가제외 | CH9: 평가제외 | CI9: 평가제외 | CK9: AA- | CL9: C | CM9: =IF(CL9="A", 100, IF(CL9="B", 85, IF(CL9="C", 70, IF(CL9="D", 55, IF(CL9="E", 40, 25))))) -> 70 | CN9: =CM9*0.015 -> 1.05 | CO9: =1603024000+297135000+252038000+143544000+112165000+57000+18304000+360000+518189000+764000+591000+10311000+27000000 -> 2983482000 | CP9: =(CO9/N9)*100 -> 97.437289 | CQ9: =IF(CP9<3, 100, IF(CP9<10, 80, IF(CP9<35, 60, IF(CP9<100, 40, IF(CP9>=100, 20))))) -> 40 | CR9: =CQ9*0.03 -> 1.2 | CS9: =_xlfn.XLOOKUP(C9, '1-1. 관계사체무보증금액 (환율 등)'!$3:$3, '1-1. 관계사체무보증금액 (환율 등)'!$33:$33) -> 15129000 | CT9: =(CS9/N9)*100 -> 0.49409675 | CU9: =IF(CT9<3, 100, IF(CT9<10, 80, IF(CT9<35, 60, IF(CT9<100, 40, 20)))) -> 100 | CV9: =CU9*0.02 -> 2 | CW9: =AE9+AJ9+AQ9+AX9+BD9+BN9+BR9+CB9+CE9+CJ9+CN9+CR9+CV9 -> 18.627503
A10: DL건설 | B10: https://dart.fss.or.kr/dsaf001/main.do?rcpNo=20230315000019 | C10: 001880 | D10: 비제조/서비스업 | E10: 건물 건설업 | F10: 도로건설공사,토목공사,건축공사,조경공사/부동산 임대,매매 | G10: 28481 | H10: 12월 | I10: 곽수윤 | J10: http://www.dlconstruction.co.kr | K10: 인천광역시 | L10: 1746816808 | M10: 748120989 | N10: 998695819 | O10: 1962419335 | P10: 81072832 | Q10: 84339672 | R10: 55421181 | S10: 22053284 | T10: 4263 | U10: 14100660 | V10: 1188 | W10: =126724+13347 -> 140071 | X10: 130403 | Y10: (학)대림학원 | Z10: 0 | AA10: 0 | AB10: =SUM(U10,V10,Z10,W10,X10) -> 14372322 | AC10: =(AB10/S10)*100 -> 65.170892 | AD10: =100-(75*(AC10-0.1))/(87-0.1) -> 43.839851 | AE10: =AD10*0.03 -> 1.3151955 | AF10: =(U10+V10)/(S10-T10-AA10)*100 -> 63.956799 | AG10: =(U10+V10+Z10+W10+X10-AA10)/(S10-T10-AA10)*100 -> 65.183493 | AH10: =AG10-AF10 -> 1.2266939 | AI10: =IF(AH10<10, 100, IF(AH10<30, 80, IF(AH10<50, 60, IF(AH10<80, 40, IF(AH10<=100, 20))))) -> 100 | AJ10: =AI10*0.04 -> 4 | AK10: 5 | AL10: 24 | AM10: 0 | AN10: =SUM(AK10:AL10) -> 29 | AO10: =(AM10/AN10)*100 -> 0 | AP10: =IF(AO10<10, 100, IF(AO10<20, 80, IF(AO10<30, 60, IF(AO10<50, 40, IF(AO10>=50, 20))))) -> 100 | AQ10: =AP10*0.02 -> 2 | AR10: 1 | AS10: =IF(L10>=2000000000, 0.5, IF(L10<2000000000, 0.25)) -> 0.25 | AT10: =AK10*AS10 -> 1.25 | AU10: =ROUNDDOWN(AT10,0) -> 1 | AV10: =(AR10-AU10)/AK10*100 -> 0 | AW10: =IF(AV10<0, 20, IF(AV10=0, 40, IF(AV10<20, 60, IF(AV10<40, 80, IF(AV10>=40, 100))))) -> 40 | AX10: =AW10*0.01 -> 0.4 | AY10: 29 | AZ10: 29 | BA10: =AR10*AY10 -> 29 | BB10: =(AZ10/BA10)*100 -> 100 | BC10: =IF(BB10<70, 25, IF(BB10<80, 50, IF(BB10<90, 75, IF(BB10>=90, 100)))) -> 100 | BD10: =BC10*0.01 -> 1 | BE10: 36788000 | BF10: 2051000 | BG10: 159000 | BH10: =SUM(BE10:BF10) -> 38839000 | BI10: =(BG10/BH10)*100 -> 0.40938232 | BJ10: =IF(D10="금융업(보험)", "금융업", IF(D10="금융업(증권)", "금융업", IF(D10="금융업(종금)", "금융업", D10))) -> 비제조/서비스업 | BK10: =AVERAGEIF(BJ:BJ, BJ10, BI:BI) -> 1.7464435 | BL10: =BI10-BK10 -> -1.3370611 | BM10: =IF(BL10<-2, 100, IF(BL10<0, 80, IF(BL10<2, 60, IF(BL10<10, 40, 20)))) -> 80 | BN10: =BM10*0.02 -> 1.6 | BO10: 0 | BP10: =(BO10/O10)*100 -> 0 | BQ10: =IF(BP10=0, 25, IF(BP10<0.1, 40, IF(BP10<0.5, 55, IF(BP10<2, 70, IF(BP10<4, 85, IF(BP10>=4, 100)))))) -> 25 | BR10: =BQ10*0.02 -> 0.5 | BS10: 722768.65 | BT10: 39904.954 | BU10: =BS10-BT10 -> 682863.7 | BV10: =BU10/O10*100 -> 0.034797033 | BW10: =AVERAGEIF(BJ:BJ, BJ10, BV:BV) -> 2.8482825 | BX10: =(BV10-BW10)^2 -> 7.9157007 | BY10: =SQRT(SUMIF(BJ:BJ, BJ10, BX:BX)/COUNTIF(BJ:BJ, BJ10)) -> 5.5697596 | BZ10: =(1-_xlfn.NORM.DIST(BV10, BW10, BY10, TRUE))*100 -> 69.326831 | CA10: =IF(BZ10<=5, 100, IF(BZ10<=15, 85, IF(BZ10<=35, 70, IF(BZ10<=60, 55, IF(BZ10<=90, 40, 25))))) -> 40 | CB10: =CA10*0.02 -> 0.8 | CC10: =(M10/N10)*100 -> 74.909795 | CD10: =IF((100-(75*(CC10-1)/(200-1)))>100, 100, IF((100-(75*(CC10-1)/(200-1)))<25, 25, (100-(75*(CC10-1)/(200-1))))) -> 72.14455 | CE10: =CD10*0.015 -> 1.0821682 | CF10: 평가제외 | CG10: 평가제외 | CH10: 평가제외 | CI10: 평가제외 | CK10: A2- | CL10: C | CM10: =IF(CL10="A", 100, IF(CL10="B", 85, IF(CL10="C", 70, IF(CL10="D", 55, IF(CL10="E", 40, 25))))) -> 70 | CN10: =CM10*0.015 -> 1.05 | CO10: 0 | CP10: =(CO10/N10)*100 -> 0 | CQ10: =IF(CP10<3, 100, IF(CP10<10, 80, IF(CP10<35, 60, IF(CP10<100, 40, IF(CP10>=100, 20))))) -> 100 | CR10: =CQ10*0.03 -> 3 | CS10: =_xlfn.XLOOKUP(C10, '1-1. 관계사체무보증금액 (환율 등)'!$3:$3, '1-1. 관계사체무보증금액 (환율 등)'!$33:$33) -> 70000000 | CT10: =(CS10/N10)*100 -> 7.0091412 | CU10: =IF(CT10<3, 100, IF(CT10<10, 80, IF(CT10<35, 60, IF(CT10<100, 40, 20)))) -> 80 | CV10: =CU10*0.02 -> 1.6 | CW10: =AE10+AJ10+AQ10+AX10+BD10+BN10+BR10+CB10+CE10+CJ10+CN10+CR10+CV10 -> 18.347364
A11: DL이앤씨 | B11: https://dart.fss.or.kr/dsaf001/main.do?rcpNo=20230315001420 | C11: 375500 | D11: 비제조/서비스업 | E11: 토목 건설업 | F11: 토목 건설 사업 | G11: 44221 | H11: 12월 | I11: 마창민 | J11: https://www.dlenc.co.kr/main.do | K11: 서울특별시 | L11: 6952036110 | M11: 3038424778 | N11: 3913611332 | O11: 5275660012 | P11: 402580787 | Q11: 469747452 | R11: 310207542 | S11: 38693623 | T11: 670930 | U11: 8957128 | V11: =13802+32264+24168+54 -> 70288 | W11: 0 | X11: 488884 | Y11: (학)대림학원 | Z11: 0 | AA11: 0 | AB11: =SUM(U11,V11,Z11,W11,X11) -> 9516300 | AC11: =(AB11/S11)*100 -> 24.593975 | AD11: =100-(75*(AC11-0.1))/(87-0.1) -> 78.860206 | AE11: =AD11*0.03 -> 2.3658062 | AF11: =(U11+V11)/(S11-T11-AA11)*100 -> 23.742179 | AG11: =(U11+V11+Z11+W11+X11-AA11)/(S11-T11-AA11)*100 -> 25.027948 | AH11: =AG11-AF11 -> 1.285769 | AI11: =IF(AH11<10, 100, IF(AH11<30, 80, IF(AH11<50, 60, IF(AH11<80, 40, IF(AH11<=100, 20))))) -> 100 | AJ11: =AI11*0.04 -> 4 | AK11: 6 | AL11: 63 | AM11: 1 | AN11: =SUM(AK11:AL11) -> 69 | AO11: =(AM11/AN11)*100 -> 1.4492754 | AP11: =IF(AO11<10, 100, IF(AO11<20, 80, IF(AO11<30, 60, IF(AO11<50, 40, IF(AO11>=50, 20))))) -> 100 | AQ11: =AP11*0.02 -> 2 | AR11: 4 | AS11: =IF(L11>=2000000000, 0.5, IF(L11<2000000000, 0.25)) -> 0.5 | AT11: =AK11*AS11 -> 3 | AU11: =ROUNDDOWN(AT11,0) -> 3 | AV11: =(AR11-AU11)/AK11*100 -> 16.666667 | AW11: =IF(AV11<0, 20, IF(AV11=0, 40, IF(AV11<20, 60, IF(AV11<40, 80, IF(AV11>=40, 100))))) -> 60 | AX11: =AW11*0.01 -> 0.6 | AY11: 9 | AZ11: =7*4+3*2 -> 34 | BA11: =AR11*AY11 -> 36 | BB11: =(AZ11/BA11)*100 -> 94.444444 | BC11: =IF(BB11<70, 25, IF(BB11<80, 50, IF(BB11<90, 75, IF(BB11>=90, 100)))) -> 100 | BD11: =BC11*0.01 -> 1 | BE11: 452654000 | BF11: 35841000 | BG11: 0 | BH11: =SUM(BE11:BF11) -> 488495000 | BI11: =(BG11/BH11)*100 -> 0 | BJ11: =IF(D11="금융업(보험)", "금융업", IF(D11="금융업(증권)", "금융업", IF(D11="금융업(종금)", "금융업", D11))) -> 비제조/서비스업 | BK11: =AVERAGEIF(BJ:BJ, BJ11, BI:BI) -> 1.7464435 | BL11: =BI11-BK11 -> -1.7464435 | BM11: =IF(BL11<-2, 100, IF(BL11<0, 80, IF(BL11<2, 60, IF(BL11<10, 40, 20)))) -> 80 | BN11: =BM11*0.02 -> 1.6 | BO11: =54558000-44000 -> 54514000 | BP11: =(BO11/O11)*100 -> 1.0333115 | BQ11: =IF(BP11=0, 25, IF(BP11<0.1, 40, IF(BP11<0.5, 55, IF(BP11<2, 70, IF(BP11<4, 85, IF(BP11>=4, 100)))))) -> 70 | BR11: =BQ11*0.02 -> 1.4 | BS11: 2146909 | BT11: 173026.47 | BU11: =BS11-BT11 -> 1973882.6 | BV11: =BU11/O11*100 -> 0.037414893 | BW11: =AVERAGEIF(BJ:BJ, BJ11, BV:BV) -> 2.8482825 | BX11: =(BV11-BW11)^2 -> 7.9009769 | BY11: =SQRT(SUMIF(BJ:BJ, BJ11, BX:BX)/COUNTIF(BJ:BJ, BJ11)) -> 5.5697596 | BZ11: =(1-_xlfn.NORM.DIST(BV11, BW11, BY11, TRUE))*100 -> 69.310324 | CA11: =IF(BZ11<=5, 100, IF(BZ11<=15, 85, IF(BZ11<=35, 70, IF(BZ11<=60, 55, IF(BZ11<=90, 40, 25))))) -> 40 | CB11: =CA11*0.02 -> 0.8 | CC11: =(M11/N11)*100 -> 77.637367 | CD11: =IF((100-(75*(CC11-1)/(200-1)))>100, 100, IF((100-(75*(CC11-1)/(200-1)))<25, 25, (100-(75*(CC11-1)/(200-1))))) -> 71.11657 | CE11: =CD11*0.015 -> 1.0667486 | CF11: 평가제외 | CG11: 평가제외 | CH11: 평가제외 | CI11: 평가제외 | CK11: A1 | CL11: A | CM11: =IF(CL11="A", 100, IF(CL11="B", 85, IF(CL11="C", 70, IF(CL11="D", 55, IF(CL11="E", 40, 25))))) -> 100 | CN11: =CM11*0.015 -> 1.5 | CO11: =244409000+5437000+38383000+4527000+20068000+20000000 -> 332824000 | CP11: =(CO11/N11)*100 -> 8.5042681 | CQ11: =IF(CP11<3, 100, IF(CP11<10, 80, IF(CP11<35, 60, IF(CP11<100, 40, IF(CP11>=100, 20))))) -> 80 | CR11: =CQ11*0.03 -> 2.4 | CS11: =_xlfn.XLOOKUP(C11, '1-1. 관계사체무보증금액 (환율 등)'!$3:$3, '1-1. 관계사체무보증금액 (환율 등)'!$33:$33) -> 1.8460304e+09 | CT11: =(CS11/N11)*100 -> 47.169487 | CU11: =IF(CT11<3, 100, IF(CT11<10, 80, IF(CT11<35, 60, IF(CT11<100, 40, 20)))) -> 40 | CV11: =CU11*0.02 -> 0.8 | CW11: =AE11+AJ11+AQ11+AX11+BD11+BN11+BR11+CB11+CE11+CJ11+CN11+CR11+CV11 -> 19.532555
A12: DN오토모티브 | B12: https://dart.fss.or.kr/dsaf001/main.do?rcpNo=20230322001200 | C12: 007340 | D12: 금속/비금속/화학업 | E12: 일차전지 및 축전지 제조업 | F12: 자동차용 밧데리 | G12: 32410 | H12: 12월 | I12: 김상헌 김인환 | J12: http://www.dnautomotive.com | K12: 경상남도 | L12: 1632577263 | M12: 965677546 | N12: 666899717 | O12: 772331699 | P12: 96511673 | Q12: 50588116 | R12: 37870319 | S12: 9994005 | T12: 1375880 | U12: 3027814 | V12: =1464000+500000+81827+2131 -> 2047958 | W12: 10000 | X12: 0 | Z12: 0 | AA12: 0 | AB12: =SUM(U12,V12,Z12,W12,X12) -> 5085772 | AC12: =(AB12/S12)*100 -> 50.888227 | AD12: =100-(75*(AC12-0.1))/(87-0.1) -> 56.166662 | AE12: =AD12*0.03 -> 1.6849999 | AF12: =(U12+V12)/(S12-T12-AA12)*100 -> 58.896477 | AG12: =(U12+V12+Z12+W12+X12-AA12)/(S12-T12-AA12)*100 -> 59.012511 | AH12: =AG12-AF12 -> 0.11603452 | AI12: =IF(AH12<10, 100, IF(AH12<30, 80, IF(AH12<50, 60, IF(AH12<80, 40, IF(AH12<=100, 20))))) -> 100 | AJ12: =AI12*0.04 -> 4 | AK12: 5 | AL12: 33 | AM12: 1 | AN12: =SUM(AK12:AL12) -> 38 | AO12: =(AM12/AN12)*100 -> 2.6315789 | AP12: =IF(AO12<10, 100, IF(AO12<20, 80, IF(AO12<30, 60, IF(AO12<50, 40, IF(AO12>=50, 20))))) -> 100 | AQ12: =AP12*0.02 -> 2 | AR12: 1 | AS12: =IF(L12>=2000000000, 0.5, IF(L12<2000000000, 0.25)) -> 0.25 | AT12: =AK12*AS12 -> 1.25 | AU12: =ROUNDDOWN(AT12,0) -> 1 | AV12: =(AR12-AU12)/AK12*100 -> 0 | AW12: =IF(AV12<0, 20, IF(AV12=0, 40, IF(AV12<20, 60, IF(AV12<40, 80, IF(AV12>=40, 100))))) -> 40 | AX12: =AW12*0.01 -> 0.4 | AY12: 21 | AZ12: 17 | BA12: =AR12*AY12 -> 21 | BB12: =(AZ12/BA12)*100 -> 80.952381 | BC12: =IF(BB12<70, 25, IF(BB12<80, 50, IF(BB12<90, 75, IF(BB12>=90, 100)))) -> 75 | BD12: =BC12*0.01 -> 0.75 | BE12: 98950122 | BF12: 4632784 | BG12: 970372 | BH12: =SUM(BE12:BF12) -> 103582906 | BI12: =(BG12/BH12)*100 -> 0.93680708 | BJ12: =IF(D12="금융업(보험)", "금융업", IF(D12="금융업(증권)", "금융업", IF(D12="금융업(종금)", "금융업", D12))) -> 금속/비금속/화학업 | BK12: =AVERAGEIF(BJ:BJ, BJ12, BI:BI) -> 3.9534119 | BL12: =BI12-BK12 -> -3.0166048 | BM12: =IF(BL12<-2, 100, IF(BL12<0, 80, IF(BL12<2, 60, IF(BL12<10, 40, 20)))) -> 100 | BN12: =BM12*0.02 -> 2 | BO12: 74012427 | BP12: =(BO12/O12)*100 -> 9.5829845 | BQ12: =IF(BP12=0, 25, IF(BP12<0.1, 40, IF(BP12<0.5, 55, IF(BP12<2, 70, IF(BP12<4, 85, IF(BP12>=4, 100)))))) -> 100 | BR12: =BQ12*0.02 -> 2 | BS12: 55551837 | BT12: 2178713.4 | BU12: =BS12-BT12 -> 53373123 | BV12: =BU12/O12*100 -> 6.9106477 | BW12: =AVERAGEIF(BJ:BJ, BJ12, BV:BV) -> 5.1474159 | BX12: =(BV12-BW12)^2 -> 3.1089867 | BY12: =SQRT(SUMIF(BJ:BJ, BJ12, BX:BX)/COUNTIF(BJ:BJ, BJ12)) -> 6.6930499 | BZ12: =(1-_xlfn.NORM.DIST(BV12, BW12, BY12, TRUE))*100 -> 39.610488 | CA12: =IF(BZ12<=5, 100, IF(BZ12<=15, 85, IF(BZ12<=35, 70, IF(BZ12<=60, 55, IF(BZ12<=90, 40, 25))))) -> 55 | CB12: =CA12*0.02 -> 1.1 | CC12: =(M12/N12)*100 -> 144.80101 | CD12: =IF((100-(75*(CC12-1)/(200-1)))>100, 100, IF((100-(75*(CC12-1)/(200-1)))<25, 25, (100-(75*(CC12-1)/(200-1))))) -> 45.803638 | CE12: =CD12*0.015 -> 0.68705457 | CF12: 평가제외 | CG12: 평가제외 | CH12: 평가제외 | CI12: 평가제외 | CK12: 미공시 | CL12: F | CM12: =IF(CL12="A", 100, IF(CL12="B", 85, IF(CL12="C", 70, IF(CL12="D", 55, IF(CL12="E", 40, 25))))) -> 25 | CN12: =CM12*0.015 -> 0.375 | CO12: =28814000+4128000+24869000+900694000+19733000+1856000+35059000+21454000+361000+570000+10100000+1725000 -> 1049363000 | CP12: =(CO12/N12)*100 -> 157.34944 | CQ12: =IF(CP12<3, 100, IF(CP12<10, 80, IF(CP12<35, 60, IF(CP12<100, 40, IF(CP12>=100, 20))))) -> 20 | CR12: =CQ12*0.03 -> 0.6 | CS12: =_xlfn.XLOOKUP(C12, '1-1. 관계사체무보증금액 (환율 등)'!$3:$3, '1-1. 관계사체무보증금액 (환율 등)'!$33:$33) -> 2.6522736e+09 | CT12: =(CS12/N12)*100 -> 397.70202 | CU12: =IF(CT12<3, 100, IF(CT12<10, 80, IF(CT12<35, 60, IF(CT12<100, 40, 20)))) -> 20 | CV12: =CU12*0.02 -> 0.4 | CW12: =AE12+AJ12+AQ12+AX12+BD12+BN12+BR12+CB12+CE12+CJ12+CN12+CR12+CV12 -> 15.997054
A13: DSR | B13: https://dart.fss.or.kr/dsaf001/main.do?rcpNo=20230320000736 | C13: 155660 | D13: 금속/비금속/화학업 | E13: 1차 비철금속 제조업 | F13: 합섬섬유로프 | G13: 41409 | H13: 12월 | I13: 홍석빈 | J13: http://www.dsr.com | K13: 부산광역시 | L13: 279626168 | M13: 94093073 | N13: 185533095 | O13: 246405810 | P13: 31078773 | Q13: 26528544 | R13: 19234317 | S13: 16000000 | T13: 0 | U13: =5080000+1377450 -> 6457450 | V13: =1267950+693719+600000+125000+123842 -> 2810511 | W13: =620500+561200+320500+162280 -> 1664480 | X13: 0 | Z13: 0 | AA13: 461000 | AB13: =SUM(U13,V13,Z13,W13,X13) -> 10932441 | AC13: =(AB13/S13)*100 -> 68.327756 | AD13: =100-(75*(AC13-0.1))/(87-0.1) -> 41.115285 | AE13: =AD13*0.03 -> 1.2334586 | AF13: =(U13+V13)/(S13-T13-AA13)*100 -> 59.643227 | AG13: =(U13+V13+Z13+W13+X13-AA13)/(S13-T13-AA13)*100 -> 67.388127 | AH13: =AG13-AF13 -> 7.7448999 | AI13: =IF(AH13<10, 100, IF(AH13<30, 80, IF(AH13<50, 60, IF(AH13<80, 40, IF(AH13<=100, 20))))) -> 100 | AJ13: =AI13*0.04 -> 4 | AK13: 5 | AL13: 10 | AM13: 3 | AN13: =SUM(AK13:AL13) -> 15 | AO13: =(AM13/AN13)*100 -> 20 | AP13: =IF(AO13<10, 100, IF(AO13<20, 80, IF(AO13<30, 60, IF(AO13<50, 40, IF(AO13>=50, 20))))) -> 60 | AQ13: =AP13*0.02 -> 1.2 | AR13: 3 | AS13: =IF(L13>=2000000000, 0.5, IF(L13<2000000000, 0.25)) -> 0.25 | AT13: =AK13*AS13 -> 1.25 | AU13: =ROUNDDOWN(AT13,0) -> 1 | AV13: =(AR13-AU13)/AK13*100 -> 40 | AW13: =IF(AV13<0, 20, IF(AV13=0, 40, IF(AV13<20, 60, IF(AV13<40, 80, IF(AV13>=40, 100))))) -> 100 | AX13: =AW13*0.01 -> 1 | AY13: 11 | AZ13: =11+4+10 -> 25 | BA13: =AR13*AY13 -> 33 | BB13: =(AZ13/BA13)*100 -> 75.757576 | BC13: =IF(BB13<70, 25, IF(BB13<80, 50, IF(BB13<90, 75, IF(BB13>=90, 100)))) -> 50 | BD13: =BC13*0.01 -> 0.5 | BE13: 4901481 | BF13: 373273 | BG13: 0 | BH13: =SUM(BE13:BF13) -> 5274754 | BI13: =(BG13/BH13)*100 -> 0 | BJ13: =IF(D13="금융업(보험)", "금융업", IF(D13="금융업(증권)", "금융업", IF(D13="금융업(종금)", "금융업", D13))) -> 금속/비금속/화학업 | BK13: =AVERAGEIF(BJ:BJ, BJ13, BI:BI) -> 3.9534119 | BL13: =BI13-BK13 -> -3.9534119 | BM13: =IF(BL13<-2, 100, IF(BL13<0, 80, IF(BL13<2, 60, IF(BL13<10, 40, 20)))) -> 100 | BN13: =BM13*0.02 -> 2 | BO13: 2711000 | BP13: =(BO13/O13)*100 -> 1.1002176 | BQ13: =IF(BP13=0, 25, IF(BP13<0.1, 40, IF(BP13<0.5, 55, IF(BP13<2, 70, IF(BP13<4, 85, IF(BP13>=4, 100)))))) -> 70 | BR13: =BQ13*0.02 -> 1.4 | BS13: 54854077 | BT13: 82975.772 | BU13: =BS13-BT13 -> 54771101 | BV13: =BU13/O13*100 -> 22.228007 | BW13: =AVERAGEIF(BJ:BJ, BJ13, BV:BV) -> 5.1474159 | BX13: =(BV13-BW13)^2 -> 291.7466 | BY13: =SQRT(SUMIF(BJ:BJ, BJ13, BX:BX)/COUNTIF(BJ:BJ, BJ13)) -> 6.6930499 | BZ13: =(1-_xlfn.NORM.DIST(BV13, BW13, BY13, TRUE))*100 -> 0.53554911 | CA13: =IF(BZ13<=5, 100, IF(BZ13<=15, 85, IF(BZ13<=35, 70, IF(BZ13<=60, 55, IF(BZ13<=90, 40, 25))))) -> 100 | CB13: =CA13*0.02 -> 2 | CC13: =(M13/N13)*100 -> 50.714981 | CD13: =IF((100-(75*(CC13-1)/(200-1)))>100, 100, IF((100-(75*(CC13-1)/(200-1)))<25, 25, (100-(75*(CC13-1)/(200-1))))) -> 81.263198 | CE13: =CD13*0.015 -> 1.218948 | CF13: 평가제외 | CG13: 평가제외 | CH13: 평가제외 | CI13: 평가제외 | CK13: 미공시 | CL13: F | CM13: =IF(CL13="A", 100, IF(CL13="B", 85, IF(CL13="C", 70, IF(CL13="D", 55, IF(CL13="E", 40, 25))))) -> 25 | CN13: =CM13*0.015 -> 0.375 | CO13: =2201000+11975000+5355000+10000 -> 19541000 | CP13: =(CO13/N13)*100 -> 10.532353 | CQ13: =IF(CP13<3, 100, IF(CP13<10, 80, IF(CP13<35, 60, IF(CP13<100, 40, IF(CP13>=100, 20))))) -> 60 | CR13: =CQ13*0.03 -> 1.8 | CS13: =_xlfn.XLOOKUP(C13, '1-1. 관계사체무보증금액 (환율 등)'!$3:$3, '1-1. 관계사체무보증금액 (환율 등)'!$33:$33) -> 10297639 | CT13: =(CS13/N13)*100 -> 5.5502979 | CU13: =IF(CT13<3, 100, IF(CT13<10, 80, IF(CT13<35, 60, IF(CT13<100, 40, 20)))) -> 80 | CV13: =CU13*0.02 -> 1.6 | CW13: =AE13+AJ13+AQ13+AX13+BD13+BN13+BR13+CB13+CE13+CJ13+CN13+CR13+CV13 -> 18.327407
A14: DSR제강 | B14: https://dart.fss.or.kr/dsaf001/main.do?rcpNo=20230320000604 | C14: 069730 | D14: 금속/비금속/화학업 | E14: 1차 철강 제조업 | F14: 와이어로프,각종 경강선,철선제품,PC강선,아연도 강연선 제조 | G14: 37649 | H14: 12월 | I14: 홍하종, 홍석빈 (각자 대표이사) | J14: http://www.dsrcorp.com | K14: 전라남도 | L14: 259398157 | M14: 76302600 | N14: 183095557 | O14: 261687162 | P14: 26367414 | Q14: 33010683 | R14: 28926448 | S14: 14400000 | T14: 0 | U14: 3822430 | V14: =2441820+510274+361228+311575+184430+108000+60000 -> 3977327 | W14: 0 | X14: 0 | Z14: 461000 | AA14: 5080 | AB14: =SUM(U14,V14,Z14,W14,X14) -> 8260757 | AC14: =(AB14/S14)*100 -> 57.366368 | AD14: =100-(75*(AC14-0.1))/(87-0.1) -> 50.575632 | AE14: =AD14*0.03 -> 1.517269 | AF14: =(U14+V14)/(S14-T14-AA14)*100 -> 54.184094 | AG14: =(U14+V14+Z14+W14+X14-AA14)/(S14-T14-AA14)*100 -> 57.351323 | AH14: =AG14-AF14 -> 3.1672284 | AI14: =IF(AH14<10, 100, IF(AH14<30, 80, IF(AH14<50, 60, IF(AH14<80, 40, IF(AH14<=100, 20))))) -> 100 | AJ14: =AI14*0.04 -> 4 | AK14: 8 | AL14: 3 | AM14: 4 | AN14: =SUM(AK14:AL14) -> 11 | AO14: =(AM14/AN14)*100 -> 36.363636 | AP14: =IF(AO14<10, 100, IF(AO14<20, 80, IF(AO14<30, 60, IF(AO14<50, 40, IF(AO14>=50, 20))))) -> 40 | AQ14: =AP14*0.02 -> 0.8 | AR14: 3 | AS14: =IF(L14>=2000000000, 0.5, IF(L14<2000000000, 0.25)) -> 0.25 | AT14: =AK14*AS14 -> 2 | AU14: =ROUNDDOWN(AT14,0) -> 2 | AV14: =(AR14-AU14)/AK14*100 -> 12.5 | AW14: =IF(AV14<0, 20, IF(AV14=0, 40, IF(AV14<20, 60, IF(AV14<40, 80, IF(AV14>=40, 100))))) -> 60 | AX14: =AW14*0.01 -> 0.6 | AY14: 9 | AZ14: =9+5+8+3 -> 25 | BA14: =AR14*AY14 -> 27 | BB14: =(AZ14/BA14)*100 -> 92.592593 | BC14: =IF(BB14<70, 25, IF(BB14<80, 50, IF(BB14<90, 75, IF(BB14>=90, 100)))) -> 100 | BD14: =BC14*0.01 -> 1 | BE14: =4140857+1683023 -> 5823880 | BF14: =315559+108562 -> 424121 | BG14: 36991 | BH14: =SUM(BE14:BF14) -> 6248001 | BI14: =(BG14/BH14)*100 -> 0.59204536 | BJ14: =IF(D14="금융업(보험)", "금융업", IF(D14="금융업(증권)", "금융업", IF(D14="금융업(종금)", "금융업", D14))) -> 금속/비금속/화학업 | BK14: =AVERAGEIF(BJ:BJ, BJ14, BI:BI) -> 3.9534119 | BL14: =BI14-BK14 -> -3.3613665 | BM14: =IF(BL14<-2, 100, IF(BL14<0, 80, IF(BL14<2, 60, IF(BL14<10, 40, 20)))) -> 100 | BN14: =BM14*0.02 -> 2 | BO14: 1286949 | BP14: =(BO14/O14)*100 -> 0.49178912 | BQ14: =IF(BP14=0, 25, IF(BP14<0.1, 40, IF(BP14<0.5, 55, IF(BP14<2, 70, IF(BP14<4, 85, IF(BP14>=4, 100)))))) -> 55 | BR14: =BQ14*0.02 -> 1.1 | BS14: 2319003.1 | BT14: 194359.58 | BU14: =BS14-BT14 -> 2124643.5 | BV14: =BU14/O14*100 -> 0.81190207 | BW14: =AVERAGEIF(BJ:BJ, BJ14, BV:BV) -> 5.1474159 | BX14: =(BV14-BW14)^2 -> 18.79668 | BY14: =SQRT(SUMIF(BJ:BJ, BJ14, BX:BX)/COUNTIF(BJ:BJ, BJ14)) -> 6.6930499 | BZ14: =(1-_xlfn.NORM.DIST(BV14, BW14, BY14, TRUE))*100 -> 74.143106 | CA14: =IF(BZ14<=5, 100, IF(BZ14<=15, 85, IF(BZ14<=35, 70, IF(BZ14<=60, 55, IF(BZ14<=90, 40, 25))))) -> 40 | CB14: =CA14*0.02 -> 0.8 | CC14: =(M14/N14)*100 -> 41.673649 | CD14: =IF((100-(75*(CC14-1)/(200-1)))>100, 100, IF((100-(75*(CC14-1)/(200-1)))<25, 25, (100-(75*(CC14-1)/(200-1))))) -> 84.670735 | CE14: =CD14*0.015 -> 1.270061 | CF14: 평가제외 | CG14: 평가제외 | CH14: 평가제외 | CI14: 평가제외 | CK14: 미공시 | CL14: F | CM14: =IF(CL14="A", 100, IF(CL14="B", 85, IF(CL14="C", 70, IF(CL14="D", 55, IF(CL14="E", 40, 25))))) -> 25 | CN14: =CM14*0.015 -> 0.375 | CO14: =64619000+1730000+98000+10000 -> 66457000 | CP14: =(CO14/N14)*100 -> 36.296348 | CQ14: =IF(CP14<3, 100, IF(CP14<10, 80, IF(CP14<35, 60, IF(CP14<100, 40, IF(CP14>=100, 20))))) -> 40 | CR14: =CQ14*0.03 -> 1.2 | CS14: =_xlfn.XLOOKUP(C14, '1-1. 관계사체무보증금액 (환율 등)'!$3:$3, '1-1. 관계사체무보증금액 (환율 등)'!$33:$33) -> 10297639 | CT14: =(CS14/N14)*100 -> 5.6241886 | CU14: =IF(CT14<3, 100, IF(CT14<10, 80, IF(CT14<35, 60, IF(CT14<100, 40, 20)))) -> 80 | CV14: =CU14*0.02 -> 1.6 | CW14: =AE14+AJ14+AQ14+AX14+BD14+BN14+BR14+CB14+CE14+CJ14+CN14+CR14+CV14 -> 16.26233
A15: F&F | B15: https://dart.fss.or.kr/dsaf001/main.do?rcpNo=20230831001367 | C15: 383220 | D15: 식약/섬유/종이업 | E15: 봉제의복 제조업 | F15: MLB, MLB KIDS, DISCOVERY 등 패션의류제품 | G15: 44337 | H15: 12월 | I15: 김창수 | J15: http://www.fnf.co.kr | K15: 서울특별시 | L15: 1329134616 | M15: 413421862 | N15: 915712754 | O15: 1615587865 | P15: 523701828 | Q15: 528169893 | R15: 385627456 | S15: 38307075 | T15: 164334 | U15: =11700060+8811400 -> 20511460 | V15: =383075+191540+191540+546550+322125+379590+135470+84870 -> 2234760 | W15: 0 | X15: 0 | Z15: 0 | AA15: 0 | AB15: =SUM(U15,V15,Z15,W15,X15) -> 22746220 | AC15: =(AB15/S15)*100 -> 59.37864 | AD15: =100-(75*(AC15-0.1))/(87-0.1) -> 48.838919 | AE15: =AD15*0.03 -> 1.4651676 | AF15: =(U15+V15)/(S15-T15-AA15)*100 -> 59.634466 | AG15: =(U15+V15+Z15+W15+X15-AA15)/(S15-T15-AA15)*100 -> 59.634466 | AH15: =AG15-AF15 -> 0 | AI15: =IF(AH15<10, 100, IF(AH15<30, 80, IF(AH15<50, 60, IF(AH15<80, 40, IF(AH15<=100, 20))))) -> 100 | AJ15: =AI15*0.04 -> 4 | AK15: 6 | AL15: 17 | AM15: 2 | AN15: =SUM(AK15:AL15) -> 23 | AO15: =(AM15/AN15)*100 -> 8.6956522 | AP15: =IF(AO15<10, 100, IF(AO15<20, 80, IF(AO15<30, 60, IF(AO15<50, 40, IF(AO15>=50, 20))))) -> 100 | AQ15: =AP15*0.02 -> 2 | AR15: 2 | AS15: =IF(L15>=2000000000, 0.5, IF(L15<2000000000, 0.25)) -> 0.25 | AT15: =AK15*AS15 -> 1.5 | AU15: =ROUNDDOWN(AT15,0) -> 1 | AV15: =(AR15-AU15)/AK15*100 -> 16.666667 | AW15: =IF(AV15<0, 20, IF(AV15=0, 40, IF(AV15<20, 60, IF(AV15<40, 80, IF(AV15>=40, 100))))) -> 60 | AX15: =AW15*0.01 -> 0.6 | AY15: 11 | AZ15: =11+5 -> 16 | BA15: =AR15*AY15 -> 22 | BB15: =(AZ15/BA15)*100 -> 72.727273 | BC15: =IF(BB15<70, 25, IF(BB15<80, 50, IF(BB15<90, 75, IF(BB15>=90, 100)))) -> 50 | BD15: =BC15*0.01 -> 0.5 | BE15: 27577219 | BF15: 2714245 | BG15: 284451 | BH15: =SUM(BE15:BF15) -> 30291464 | BI15: =(BG15/BH15)*100 -> 0.93904672 | BJ15: =IF(D15="금융업(보험)", "금융업", IF(D15="금융업(증권)", "금융업", IF(D15="금융업(종금)", "금융업", D15))) -> 식약/섬유/종이업 | BK15: =AVERAGEIF(BJ:BJ, BJ15, BI:BI) -> 2.1999361 | BL15: =BI15-BK15 -> -1.2608893 | BM15: =IF(BL15<-2, 100, IF(BL15<0, 80, IF(BL15<2, 60, IF(BL15<10, 40, 20)))) -> 80 | BN15: =BM15*0.02 -> 1.6 | BO15: 0 | BP15: =(BO15/O15)*100 -> 0 | BQ15: =IF(BP15=0, 25, IF(BP15<0.1, 40, IF(BP15<0.5, 55, IF(BP15<2, 70, IF(BP15<4, 85, IF(BP15>=4, 100)))))) -> 25 | BR15: =BQ15*0.02 -> 0.5 | BS15: 8692977.8 | BT15: 0 | BU15: =BS15-BT15 -> 8692977.8 | BV15: =BU15/O15*100 -> 0.53806902 | BW15: =AVERAGEIF(BJ:BJ, BJ15, BV:BV) -> 5.0508176 | BX15: =(BV15-BW15)^2 -> 20.3649 | BY15: =SQRT(SUMIF(BJ:BJ, BJ15, BX:BX)/COUNTIF(BJ:BJ, BJ15)) -> 6.9871618 | BZ15: =(1-_xlfn.NORM.DIST(BV15, BW15, BY15, TRUE))*100 -> 74.081593 | CA15: =IF(BZ15<=5, 100, IF(BZ15<=15, 85, IF(BZ15<=35, 70, IF(BZ15<=60, 55, IF(BZ15<=90, 40, 25))))) -> 40 | CB15: =CA15*0.02 -> 0.8 | CC15: =(M15/N15)*100 -> 45.147549 | CD15: =IF((100-(75*(CC15-1)/(200-1)))>100, 100, IF((100-(75*(CC15-1)/(200-1)))<25, 25, (100-(75*(CC15-1)/(200-1))))) -> 83.361477 | CE15: =CD15*0.015 -> 1.2504221 | CF15: 평가제외 | CG15: 평가제외 | CH15: 평가제외 | CI15: 평가제외 | CK15: 미공시 | CL15: F | CM15: =IF(CL15="A", 100, IF(CL15="B", 85, IF(CL15="C", 70, IF(CL15="D", 55, IF(CL15="E", 40, 25))))) -> 25 | CN15: =CM15*0.015 -> 0.375 | CO15: =4682000+2888000+116000+1813000+23496000+71531000+11512000+2000000 -> 118038000 | CP15: =(CO15/N15)*100 -> 12.890287 | CQ15: =IF(CP15<3, 100, IF(CP15<10, 80, IF(CP15<35, 60, IF(CP15<100, 40, IF(CP15>=100, 20))))) -> 60 | CR15: =CQ15*0.03 -> 1.8 | CS15: =_xlfn.XLOOKUP(C15, '1-1. 관계사체무보증금액 (환율 등)'!$3:$3, '1-1. 관계사체무보증금액 (환율 등)'!$33:$33) -> 41070381 | CT15: =(CS15/N15)*100 -> 4.4850725 | CU15: =IF(CT15<3, 100, IF(CT15<10, 80, IF(CT15<35, 60, IF(CT15<100, 40, 20)))) -> 80 | CV15: =CU15*0.02 -> 1.6 | CW15: =AE15+AJ15+AQ15+AX15+BD15+BN15+BR15+CB15+CE15+CJ15+CN15+CR15+CV15 -> 16.49059
A16: GS건설 | B16: https://dart.fss.or.kr/dsaf001/main.do?rcpNo=20230316001014 | C16: 006360 | D16: 비제조/서비스업 | E16: 건물 건설업 | F16: 토목공사,건축공사,주택공사,산업플랜트공사,리모델링공사,시설물유지관리공사/산업설비설계,감리 용역,수출입/에너지관리 진단,연구개발 | G16: 29801 | H16: 12월 | I16: 허창수, 임병용(각자 대표이사) | J16: http://www.gsconst.co.kr/ | K16: 서울특별시 | L16: 12739404443 | M16: 7806315499 | N16: 4933088944 | O16: 8613702892 | P16: 281011393 | Q16: 360875361 | R16: 240672686 | S16: 85581490 | T16: 692595 | U16: =7089463 -> 7089463 | V16: =24604+1331162+1288824+282054+21429+3035643+439462+29588+2433477+300765+246081+1529727+953879+15000+10000 -> 11941695 | W16: =1756+1666+80+7056+144+400+840+1330 -> 13272 | X16: 1201460 | Y16: 재단법인 남촌재단 | Z16: 0 | AA16: 0 | AB16: =SUM(U16,V16,Z16,W16,X16) -> 20245890 | AC16: =(AB16/S16)*100 -> 23.656856 | AD16: =100-(75*(AC16-0.1))/(87-0.1) -> 79.668996 | AE16: =AD16*0.03 -> 2.3900699 | AF16: =(U16+V16)/(S16-T16-AA16)*100 -> 22.418902 | AG16: =(U16+V16+Z16+W16+X16-AA16)/(S16-T16-AA16)*100 -> 23.849869 | AH16: =AG16-AF16 -> 1.4309669 | AI16: =IF(AH16<10, 100, IF(AH16<30, 80, IF(AH16<50, 60, IF(AH16<80, 40, IF(AH16<=100, 20))))) -> 100 | AJ16: =AI16*0.04 -> 4 | AK16: 7 | AL16: 46 | AM16: 3 | AN16: =SUM(AK16:AL16) -> 53 | AO16: =(AM16/AN16)*100 -> 5.6603774 | AP16: =IF(AO16<10, 100, IF(AO16<20, 80, IF(AO16<30, 60, IF(AO16<50, 40, IF(AO16>=50, 20))))) -> 100 | AQ16: =AP16*0.02 -> 2 | AR16: 4 | AS16: =IF(L16>=2000000000, 0.5, IF(L16<2000000000, 0.25)) -> 0.5 | AT16: =AK16*AS16 -> 3.5 | AU16: =ROUNDDOWN(AT16,0) -> 3 | AV16: =(AR16-AU16)/AK16*100 -> 14.285714 | AW16: =IF(AV16<0, 20, IF(AV16=0, 40, IF(AV16<20, 60, IF(AV16<40, 80, IF(AV16>=40, 100))))) -> 60 | AX16: =AW16*0.01 -> 0.6 | AY16: 8 | AZ16: =4*2+3+4+2+4*3 -> 29 | BA16: =AR16*AY16 -> 32 | BB16: =(AZ16/BA16)*100 -> 90.625 | BC16: =IF(BB16<70, 25, IF(BB16<80, 50, IF(BB16<90, 75, IF(BB16>=90, 100)))) -> 100 | BD16: =BC16*0.01 -> 1 | BE16: 201263000 | BF16: 20845000 | BG16: 0 | BH16: =SUM(BE16:BF16) -> 222108000 | BI16: =(BG16/BH16)*100 -> 0 | BJ16: =IF(D16="금융업(보험)", "금융업", IF(D16="금융업(증권)", "금융업", IF(D16="금융업(종금)", "금융업", D16))) -> 비제조/서비스업 | BK16: =AVERAGEIF(BJ:BJ, BJ16, BI:BI) -> 1.7464435 | BL16: =BI16-BK16 -> -1.7464435 | BM16: =IF(BL16<-2, 100, IF(BL16<0, 80, IF(BL16<2, 60, IF(BL16<10, 40, 20)))) -> 80 | BN16: =BM16*0.02 -> 1.6 | BO16: =(34670-3)*1000 -> 34667000 | BP16: =(BO16/O16)*100 -> 0.40246338 | BQ16: =IF(BP16=0, 25, IF(BP16<0.1, 40, IF(BP16<0.5, 55, IF(BP16<2, 70, IF(BP16<4, 85, IF(BP16>=4, 100)))))) -> 55 | BR16: =BQ16*0.02 -> 1.1 | BS16: 23550198 | BT16: 452414.84 | BU16: =BS16-BT16 -> 23097783 | BV16: =BU16/O16*100 -> 0.26815161 | BW16: =AVERAGEIF(BJ:BJ, BJ16, BV:BV) -> 2.8482825 | BX16: =(BV16-BW16)^2 -> 6.6570756 | BY16: =SQRT(SUMIF(BJ:BJ, BJ16, BX:BX)/COUNTIF(BJ:BJ, BJ16)) -> 5.5697596 | BZ16: =(1-_xlfn.NORM.DIST(BV16, BW16, BY16, TRUE))*100 -> 67.840354 | CA16: =IF(BZ16<=5, 100, IF(BZ16<=15, 85, IF(BZ16<=35, 70, IF(BZ16<=60, 55, IF(BZ16<=90, 40, 25))))) -> 40 | CB16: =CA16*0.02 -> 0.8 | CC16: =(M16/N16)*100 -> 158.24396 | CD16: =IF((100-(75*(CC16-1)/(200-1)))>100, 100, IF((100-(75*(CC16-1)/(200-1)))<25, 25, (100-(75*(CC16-1)/(200-1))))) -> 40.737199 | CE16: =CD16*0.015 -> 0.61105799 | CF16: 평가제외 | CG16: 평가제외 | CH16: 평가제외 | CI16: 평가제외 | CK16: A+ | CL16: C | CM16: =IF(CL16="A", 100, IF(CL16="B", 85, IF(CL16="C", 70, IF(CL16="D", 55, IF(CL16="E", 40, 25))))) -> 70 | CN16: =CM16*0.015 -> 1.05 | CO16: =2176000+91256000+337000+3067000+534000+9380000+100000+20152000+248498000+61437000+20243000+1226000+6902000+77588000+1000+18754000+584000+23916000+15599000+8021000+5000000+9769000+68500000+23866000+1363000+10000000+16005000+6000000+30540000+62000000+10181000+20000+3245000+639720000+22277000+4000000+100000+25879000+98005000+49489000+1000+15218000+8654000+4500000+205000+13000000+6000+37000000+5000 -> 1774319000 | CP16: =(CO16/N16)*100 -> 35.967707 | CQ16: =IF(CP16<3, 100, IF(CP16<10, 80, IF(CP16<35, 60, IF(CP16<100, 40, IF(CP16>=100, 20))))) -> 40 | CR16: =CQ16*0.03 -> 1.2 | CS16: =_xlfn.XLOOKUP(C16, '1-1. 관계사체무보증금액 (환율 등)'!$3:$3, '1-1. 관계사체무보증금액 (환율 등)'!$33:$33) -> 2.0250619e+09 | CT16: =(CS16/N16)*100 -> 41.050587 | CU16: =IF(CT16<3, 100, IF(CT16<10, 80, IF(CT16<35, 60, IF(CT16<100, 40, 20)))) -> 40 | CV16: =CU16*0.02 -> 0.8 | CW16: =AE16+AJ16+AQ16+AX16+BD16+BN16+BR16+CB16+CE16+CJ16+CN16+CR16+CV16 -> 17.151128
